[INFO]	2020-04-17 18:29:08,816	module:trn_receiving_autorace	command.handle:67	scheduleData: スケジュール監視　Start
[INFO]	2020-04-17 18:29:08,817	module:trn_receiving_autorace	command.handle:70	scheduleData: スケジュール監視　End
[INFO]	2020-04-17 18:29:08,822	module:trn_receiving_autorace	command.handle:81	resultData: レース結果監視　Start
[INFO]	2020-04-17 18:29:08,822	module:trn_receiving_autorace	command.handle:84	resultData: レース結果監視　End
[INFO]	2020-04-17 18:29:22,969	module:watchdoc	command.on_created:53	created Start:dabdcd0001-080134-092808013400000000.dat
[INFO]	2020-04-17 18:29:22,970	module:watchdoc	command.on_created:56	created End:
[INFO]	2020-04-17 18:29:22,999	module:trn_Schedule	command.insert_or_update_Trn_Schedule:195	内容:insert_Trn_Schedule Start:詳細:ファイルデータ:2020190926
[INFO]	2020-04-17 18:29:23,003	module:trn_Schedule	command.insert_or_update_Trn_Schedule:197	内容:insert_Trn_Schedule End
[INFO]	2020-04-17 18:29:23,003	module:trn_Schedule	command.insert_or_update_Trn_Schedule:199	内容:update_Trn_Schedule Start:詳細:ファイルデータ:20190926 412               201909281412                                           
[INFO]	2020-04-17 18:29:23,042	module:trn_Schedule	command.insert_or_update_Trn_Schedule:201	内容:update_Trn_Schedule End
[WARNING]	2020-04-20 09:24:34,640	module:log	django.request.log_response:228	Not Found: /favicon.ico
[ERROR]	2020-04-20 09:24:57,683	module:log	django.request.log_response:228	Internal Server Error: /app_ckeiba/
Traceback (most recent call last):
  File "/usr/local/lib/python3.7/site-packages/django/db/backends/utils.py", line 85, in _execute
    return self.cursor.execute(sql, params)
  File "/usr/local/lib/python3.7/site-packages/django/db/backends/mysql/base.py", line 71, in execute
    return self.cursor.execute(query, args)
  File "/usr/local/lib/python3.7/site-packages/pymysql/cursors.py", line 165, in execute
    result = self._query(query)
  File "/usr/local/lib/python3.7/site-packages/pymysql/cursors.py", line 321, in _query
    conn.query(q)
  File "/usr/local/lib/python3.7/site-packages/pymysql/connections.py", line 860, in query
    self._affected_rows = self._read_query_result(unbuffered=unbuffered)
  File "/usr/local/lib/python3.7/site-packages/pymysql/connections.py", line 1061, in _read_query_result
    result.read()
  File "/usr/local/lib/python3.7/site-packages/pymysql/connections.py", line 1349, in read
    first_packet = self.connection._read_packet()
  File "/usr/local/lib/python3.7/site-packages/pymysql/connections.py", line 1018, in _read_packet
    packet.check_error()
  File "/usr/local/lib/python3.7/site-packages/pymysql/connections.py", line 384, in check_error
    err.raise_mysql_exception(self._data)
  File "/usr/local/lib/python3.7/site-packages/pymysql/err.py", line 107, in raise_mysql_exception
    raise errorclass(errno, errval)
pymysql.err.InternalError: (1054, "Unknown column 'app_ckeiba_tran_systemstatus.Environment_id' in 'field list'")

The above exception was the direct cause of the following exception:

Traceback (most recent call last):
  File "/usr/local/lib/python3.7/site-packages/django/core/handlers/exception.py", line 34, in inner
    response = get_response(request)
  File "/usr/local/lib/python3.7/site-packages/django/core/handlers/base.py", line 126, in _get_response
    response = self.process_exception_by_middleware(e, request)
  File "/usr/local/lib/python3.7/site-packages/django/core/handlers/base.py", line 124, in _get_response
    response = wrapped_callback(request, *callback_args, **callback_kwargs)
  File "./app_ckeiba/views.py", line 24, in index
    tran_system = Tran_Systemstatus.objects.all().first() # ★ システム状態の1件目を見てるだけなので、ここは要検討
  File "/usr/local/lib/python3.7/site-packages/django/db/models/query.py", line 605, in first
    for obj in (self if self.ordered else self.order_by('pk'))[:1]:
  File "/usr/local/lib/python3.7/site-packages/django/db/models/query.py", line 268, in __iter__
    self._fetch_all()
  File "/usr/local/lib/python3.7/site-packages/django/db/models/query.py", line 1186, in _fetch_all
    self._result_cache = list(self._iterable_class(self))
  File "/usr/local/lib/python3.7/site-packages/django/db/models/query.py", line 54, in __iter__
    results = compiler.execute_sql(chunked_fetch=self.chunked_fetch, chunk_size=self.chunk_size)
  File "/usr/local/lib/python3.7/site-packages/django/db/models/sql/compiler.py", line 1065, in execute_sql
    cursor.execute(sql, params)
  File "/usr/local/lib/python3.7/site-packages/django/db/backends/utils.py", line 100, in execute
    return super().execute(sql, params)
  File "/usr/local/lib/python3.7/site-packages/django/db/backends/utils.py", line 68, in execute
    return self._execute_with_wrappers(sql, params, many=False, executor=self._execute)
  File "/usr/local/lib/python3.7/site-packages/django/db/backends/utils.py", line 77, in _execute_with_wrappers
    return executor(sql, params, many, context)
  File "/usr/local/lib/python3.7/site-packages/django/db/backends/utils.py", line 85, in _execute
    return self.cursor.execute(sql, params)
  File "/usr/local/lib/python3.7/site-packages/django/db/utils.py", line 89, in __exit__
    raise dj_exc_value.with_traceback(traceback) from exc_value
  File "/usr/local/lib/python3.7/site-packages/django/db/backends/utils.py", line 85, in _execute
    return self.cursor.execute(sql, params)
  File "/usr/local/lib/python3.7/site-packages/django/db/backends/mysql/base.py", line 71, in execute
    return self.cursor.execute(query, args)
  File "/usr/local/lib/python3.7/site-packages/pymysql/cursors.py", line 165, in execute
    result = self._query(query)
  File "/usr/local/lib/python3.7/site-packages/pymysql/cursors.py", line 321, in _query
    conn.query(q)
  File "/usr/local/lib/python3.7/site-packages/pymysql/connections.py", line 860, in query
    self._affected_rows = self._read_query_result(unbuffered=unbuffered)
  File "/usr/local/lib/python3.7/site-packages/pymysql/connections.py", line 1061, in _read_query_result
    result.read()
  File "/usr/local/lib/python3.7/site-packages/pymysql/connections.py", line 1349, in read
    first_packet = self.connection._read_packet()
  File "/usr/local/lib/python3.7/site-packages/pymysql/connections.py", line 1018, in _read_packet
    packet.check_error()
  File "/usr/local/lib/python3.7/site-packages/pymysql/connections.py", line 384, in check_error
    err.raise_mysql_exception(self._data)
  File "/usr/local/lib/python3.7/site-packages/pymysql/err.py", line 107, in raise_mysql_exception
    raise errorclass(errno, errval)
django.db.utils.InternalError: (1054, "Unknown column 'app_ckeiba_tran_systemstatus.Environment_id' in 'field list'")
[ERROR]	2020-04-20 09:25:12,260	module:log	django.request.log_response:228	Internal Server Error: /admin/app_ckeiba/tran_systemstatus/add/
Traceback (most recent call last):
  File "/usr/local/lib/python3.7/site-packages/django/db/backends/utils.py", line 85, in _execute
    return self.cursor.execute(sql, params)
  File "/usr/local/lib/python3.7/site-packages/django/db/backends/mysql/base.py", line 71, in execute
    return self.cursor.execute(query, args)
  File "/usr/local/lib/python3.7/site-packages/pymysql/cursors.py", line 165, in execute
    result = self._query(query)
  File "/usr/local/lib/python3.7/site-packages/pymysql/cursors.py", line 321, in _query
    conn.query(q)
  File "/usr/local/lib/python3.7/site-packages/pymysql/connections.py", line 860, in query
    self._affected_rows = self._read_query_result(unbuffered=unbuffered)
  File "/usr/local/lib/python3.7/site-packages/pymysql/connections.py", line 1061, in _read_query_result
    result.read()
  File "/usr/local/lib/python3.7/site-packages/pymysql/connections.py", line 1349, in read
    first_packet = self.connection._read_packet()
  File "/usr/local/lib/python3.7/site-packages/pymysql/connections.py", line 1018, in _read_packet
    packet.check_error()
  File "/usr/local/lib/python3.7/site-packages/pymysql/connections.py", line 384, in check_error
    err.raise_mysql_exception(self._data)
  File "/usr/local/lib/python3.7/site-packages/pymysql/err.py", line 107, in raise_mysql_exception
    raise errorclass(errno, errval)
pymysql.err.ProgrammingError: (1146, "Table 'prj_sports.app_ckeiba_mst_environment' doesn't exist")

The above exception was the direct cause of the following exception:

Traceback (most recent call last):
  File "/usr/local/lib/python3.7/site-packages/django/core/handlers/exception.py", line 34, in inner
    response = get_response(request)
  File "/usr/local/lib/python3.7/site-packages/django/core/handlers/base.py", line 156, in _get_response
    response = self.process_exception_by_middleware(e, request)
  File "/usr/local/lib/python3.7/site-packages/django/core/handlers/base.py", line 154, in _get_response
    response = response.render()
  File "/usr/local/lib/python3.7/site-packages/django/template/response.py", line 106, in render
    self.content = self.rendered_content
  File "/usr/local/lib/python3.7/site-packages/django/template/response.py", line 83, in rendered_content
    content = template.render(context, self._request)
  File "/usr/local/lib/python3.7/site-packages/django/template/backends/django.py", line 61, in render
    return self.template.render(context)
  File "/usr/local/lib/python3.7/site-packages/django/template/base.py", line 171, in render
    return self._render(context)
  File "/usr/local/lib/python3.7/site-packages/django/template/base.py", line 163, in _render
    return self.nodelist.render(context)
  File "/usr/local/lib/python3.7/site-packages/django/template/base.py", line 937, in render
    bit = node.render_annotated(context)
  File "/usr/local/lib/python3.7/site-packages/django/template/base.py", line 904, in render_annotated
    return self.render(context)
  File "/usr/local/lib/python3.7/site-packages/django/template/loader_tags.py", line 150, in render
    return compiled_parent._render(context)
  File "/usr/local/lib/python3.7/site-packages/django/template/base.py", line 163, in _render
    return self.nodelist.render(context)
  File "/usr/local/lib/python3.7/site-packages/django/template/base.py", line 937, in render
    bit = node.render_annotated(context)
  File "/usr/local/lib/python3.7/site-packages/django/template/base.py", line 904, in render_annotated
    return self.render(context)
  File "/usr/local/lib/python3.7/site-packages/django/template/loader_tags.py", line 150, in render
    return compiled_parent._render(context)
  File "/usr/local/lib/python3.7/site-packages/django/template/base.py", line 163, in _render
    return self.nodelist.render(context)
  File "/usr/local/lib/python3.7/site-packages/django/template/base.py", line 937, in render
    bit = node.render_annotated(context)
  File "/usr/local/lib/python3.7/site-packages/django/template/base.py", line 904, in render_annotated
    return self.render(context)
  File "/usr/local/lib/python3.7/site-packages/django/template/loader_tags.py", line 62, in render
    result = block.nodelist.render(context)
  File "/usr/local/lib/python3.7/site-packages/django/template/base.py", line 937, in render
    bit = node.render_annotated(context)
  File "/usr/local/lib/python3.7/site-packages/django/template/base.py", line 904, in render_annotated
    return self.render(context)
  File "/usr/local/lib/python3.7/site-packages/django/template/loader_tags.py", line 62, in render
    result = block.nodelist.render(context)
  File "/usr/local/lib/python3.7/site-packages/django/template/base.py", line 937, in render
    bit = node.render_annotated(context)
  File "/usr/local/lib/python3.7/site-packages/django/template/base.py", line 904, in render_annotated
    return self.render(context)
  File "/usr/local/lib/python3.7/site-packages/django/template/defaulttags.py", line 209, in render
    nodelist.append(node.render_annotated(context))
  File "/usr/local/lib/python3.7/site-packages/django/template/base.py", line 904, in render_annotated
    return self.render(context)
  File "/usr/local/lib/python3.7/site-packages/django/template/loader_tags.py", line 188, in render
    return template.render(context)
  File "/usr/local/lib/python3.7/site-packages/django/template/base.py", line 173, in render
    return self._render(context)
  File "/usr/local/lib/python3.7/site-packages/django/template/base.py", line 163, in _render
    return self.nodelist.render(context)
  File "/usr/local/lib/python3.7/site-packages/django/template/base.py", line 937, in render
    bit = node.render_annotated(context)
  File "/usr/local/lib/python3.7/site-packages/django/template/base.py", line 904, in render_annotated
    return self.render(context)
  File "/usr/local/lib/python3.7/site-packages/django/template/defaulttags.py", line 209, in render
    nodelist.append(node.render_annotated(context))
  File "/usr/local/lib/python3.7/site-packages/django/template/base.py", line 904, in render_annotated
    return self.render(context)
  File "/usr/local/lib/python3.7/site-packages/django/template/defaulttags.py", line 209, in render
    nodelist.append(node.render_annotated(context))
  File "/usr/local/lib/python3.7/site-packages/django/template/base.py", line 904, in render_annotated
    return self.render(context)
  File "/usr/local/lib/python3.7/site-packages/django/template/defaulttags.py", line 309, in render
    return nodelist.render(context)
  File "/usr/local/lib/python3.7/site-packages/django/template/base.py", line 937, in render
    bit = node.render_annotated(context)
  File "/usr/local/lib/python3.7/site-packages/django/template/base.py", line 904, in render_annotated
    return self.render(context)
  File "/usr/local/lib/python3.7/site-packages/django/template/defaulttags.py", line 309, in render
    return nodelist.render(context)
  File "/usr/local/lib/python3.7/site-packages/django/template/base.py", line 937, in render
    bit = node.render_annotated(context)
  File "/usr/local/lib/python3.7/site-packages/django/template/base.py", line 904, in render_annotated
    return self.render(context)
  File "/usr/local/lib/python3.7/site-packages/django/template/base.py", line 993, in render
    return render_value_in_context(output, context)
  File "/usr/local/lib/python3.7/site-packages/django/template/base.py", line 972, in render_value_in_context
    value = str(value)
  File "/usr/local/lib/python3.7/site-packages/django/utils/html.py", line 397, in <lambda>
    klass.__str__ = lambda self: mark_safe(klass_str(self))
  File "/usr/local/lib/python3.7/site-packages/django/forms/boundfield.py", line 33, in __str__
    return self.as_widget()
  File "/usr/local/lib/python3.7/site-packages/django/forms/boundfield.py", line 93, in as_widget
    renderer=self.form.renderer,
  File "/usr/local/lib/python3.7/site-packages/django/forms/widgets.py", line 229, in render
    context = self.get_context(name, value, attrs)
  File "/usr/local/lib/python3.7/site-packages/django/contrib/admin/widgets.py", line 293, in get_context
    'rendered_widget': self.widget.render(name, value, attrs),
  File "/usr/local/lib/python3.7/site-packages/django/forms/widgets.py", line 229, in render
    context = self.get_context(name, value, attrs)
  File "/usr/local/lib/python3.7/site-packages/django/forms/widgets.py", line 668, in get_context
    context = super().get_context(name, value, attrs)
  File "/usr/local/lib/python3.7/site-packages/django/forms/widgets.py", line 629, in get_context
    context['widget']['optgroups'] = self.optgroups(name, context['widget']['value'], attrs)
  File "/usr/local/lib/python3.7/site-packages/django/forms/widgets.py", line 577, in optgroups
    for index, (option_value, option_label) in enumerate(self.choices):
  File "/usr/local/lib/python3.7/site-packages/django/forms/models.py", line 1139, in __iter__
    for obj in queryset:
  File "/usr/local/lib/python3.7/site-packages/django/db/models/query.py", line 332, in _iterator
    yield from self._iterable_class(self, chunked_fetch=use_chunked_fetch, chunk_size=chunk_size)
  File "/usr/local/lib/python3.7/site-packages/django/db/models/query.py", line 54, in __iter__
    results = compiler.execute_sql(chunked_fetch=self.chunked_fetch, chunk_size=self.chunk_size)
  File "/usr/local/lib/python3.7/site-packages/django/db/models/sql/compiler.py", line 1065, in execute_sql
    cursor.execute(sql, params)
  File "/usr/local/lib/python3.7/site-packages/django/db/backends/utils.py", line 100, in execute
    return super().execute(sql, params)
  File "/usr/local/lib/python3.7/site-packages/django/db/backends/utils.py", line 68, in execute
    return self._execute_with_wrappers(sql, params, many=False, executor=self._execute)
  File "/usr/local/lib/python3.7/site-packages/django/db/backends/utils.py", line 77, in _execute_with_wrappers
    return executor(sql, params, many, context)
  File "/usr/local/lib/python3.7/site-packages/django/db/backends/utils.py", line 85, in _execute
    return self.cursor.execute(sql, params)
  File "/usr/local/lib/python3.7/site-packages/django/db/utils.py", line 89, in __exit__
    raise dj_exc_value.with_traceback(traceback) from exc_value
  File "/usr/local/lib/python3.7/site-packages/django/db/backends/utils.py", line 85, in _execute
    return self.cursor.execute(sql, params)
  File "/usr/local/lib/python3.7/site-packages/django/db/backends/mysql/base.py", line 71, in execute
    return self.cursor.execute(query, args)
  File "/usr/local/lib/python3.7/site-packages/pymysql/cursors.py", line 165, in execute
    result = self._query(query)
  File "/usr/local/lib/python3.7/site-packages/pymysql/cursors.py", line 321, in _query
    conn.query(q)
  File "/usr/local/lib/python3.7/site-packages/pymysql/connections.py", line 860, in query
    self._affected_rows = self._read_query_result(unbuffered=unbuffered)
  File "/usr/local/lib/python3.7/site-packages/pymysql/connections.py", line 1061, in _read_query_result
    result.read()
  File "/usr/local/lib/python3.7/site-packages/pymysql/connections.py", line 1349, in read
    first_packet = self.connection._read_packet()
  File "/usr/local/lib/python3.7/site-packages/pymysql/connections.py", line 1018, in _read_packet
    packet.check_error()
  File "/usr/local/lib/python3.7/site-packages/pymysql/connections.py", line 384, in check_error
    err.raise_mysql_exception(self._data)
  File "/usr/local/lib/python3.7/site-packages/pymysql/err.py", line 107, in raise_mysql_exception
    raise errorclass(errno, errval)
django.db.utils.ProgrammingError: (1146, "Table 'prj_sports.app_ckeiba_mst_environment' doesn't exist")
[ERROR]	2020-04-20 09:51:14,031	module:log	django.request.log_response:228	Internal Server Error: /app_ckeiba/
Traceback (most recent call last):
  File "/usr/local/lib/python3.7/site-packages/django/db/backends/utils.py", line 85, in _execute
    return self.cursor.execute(sql, params)
  File "/usr/local/lib/python3.7/site-packages/django/db/backends/mysql/base.py", line 71, in execute
    return self.cursor.execute(query, args)
  File "/usr/local/lib/python3.7/site-packages/pymysql/cursors.py", line 165, in execute
    result = self._query(query)
  File "/usr/local/lib/python3.7/site-packages/pymysql/cursors.py", line 321, in _query
    conn.query(q)
  File "/usr/local/lib/python3.7/site-packages/pymysql/connections.py", line 860, in query
    self._affected_rows = self._read_query_result(unbuffered=unbuffered)
  File "/usr/local/lib/python3.7/site-packages/pymysql/connections.py", line 1061, in _read_query_result
    result.read()
  File "/usr/local/lib/python3.7/site-packages/pymysql/connections.py", line 1349, in read
    first_packet = self.connection._read_packet()
  File "/usr/local/lib/python3.7/site-packages/pymysql/connections.py", line 1018, in _read_packet
    packet.check_error()
  File "/usr/local/lib/python3.7/site-packages/pymysql/connections.py", line 384, in check_error
    err.raise_mysql_exception(self._data)
  File "/usr/local/lib/python3.7/site-packages/pymysql/err.py", line 107, in raise_mysql_exception
    raise errorclass(errno, errval)
pymysql.err.InternalError: (1054, "Unknown column 'app_ckeiba_tran_systemstatus.Environment_id' in 'field list'")

The above exception was the direct cause of the following exception:

Traceback (most recent call last):
  File "/usr/local/lib/python3.7/site-packages/django/core/handlers/exception.py", line 34, in inner
    response = get_response(request)
  File "/usr/local/lib/python3.7/site-packages/django/core/handlers/base.py", line 126, in _get_response
    response = self.process_exception_by_middleware(e, request)
  File "/usr/local/lib/python3.7/site-packages/django/core/handlers/base.py", line 124, in _get_response
    response = wrapped_callback(request, *callback_args, **callback_kwargs)
  File "./app_ckeiba/views.py", line 27, in index
    tran_system = Tran_Systemstatus.objects.all().first() # ★ システム状態の1件目を見てるだけなので、ここは要検討
  File "/usr/local/lib/python3.7/site-packages/django/db/models/query.py", line 605, in first
    for obj in (self if self.ordered else self.order_by('pk'))[:1]:
  File "/usr/local/lib/python3.7/site-packages/django/db/models/query.py", line 268, in __iter__
    self._fetch_all()
  File "/usr/local/lib/python3.7/site-packages/django/db/models/query.py", line 1186, in _fetch_all
    self._result_cache = list(self._iterable_class(self))
  File "/usr/local/lib/python3.7/site-packages/django/db/models/query.py", line 54, in __iter__
    results = compiler.execute_sql(chunked_fetch=self.chunked_fetch, chunk_size=self.chunk_size)
  File "/usr/local/lib/python3.7/site-packages/django/db/models/sql/compiler.py", line 1065, in execute_sql
    cursor.execute(sql, params)
  File "/usr/local/lib/python3.7/site-packages/django/db/backends/utils.py", line 100, in execute
    return super().execute(sql, params)
  File "/usr/local/lib/python3.7/site-packages/django/db/backends/utils.py", line 68, in execute
    return self._execute_with_wrappers(sql, params, many=False, executor=self._execute)
  File "/usr/local/lib/python3.7/site-packages/django/db/backends/utils.py", line 77, in _execute_with_wrappers
    return executor(sql, params, many, context)
  File "/usr/local/lib/python3.7/site-packages/django/db/backends/utils.py", line 85, in _execute
    return self.cursor.execute(sql, params)
  File "/usr/local/lib/python3.7/site-packages/django/db/utils.py", line 89, in __exit__
    raise dj_exc_value.with_traceback(traceback) from exc_value
  File "/usr/local/lib/python3.7/site-packages/django/db/backends/utils.py", line 85, in _execute
    return self.cursor.execute(sql, params)
  File "/usr/local/lib/python3.7/site-packages/django/db/backends/mysql/base.py", line 71, in execute
    return self.cursor.execute(query, args)
  File "/usr/local/lib/python3.7/site-packages/pymysql/cursors.py", line 165, in execute
    result = self._query(query)
  File "/usr/local/lib/python3.7/site-packages/pymysql/cursors.py", line 321, in _query
    conn.query(q)
  File "/usr/local/lib/python3.7/site-packages/pymysql/connections.py", line 860, in query
    self._affected_rows = self._read_query_result(unbuffered=unbuffered)
  File "/usr/local/lib/python3.7/site-packages/pymysql/connections.py", line 1061, in _read_query_result
    result.read()
  File "/usr/local/lib/python3.7/site-packages/pymysql/connections.py", line 1349, in read
    first_packet = self.connection._read_packet()
  File "/usr/local/lib/python3.7/site-packages/pymysql/connections.py", line 1018, in _read_packet
    packet.check_error()
  File "/usr/local/lib/python3.7/site-packages/pymysql/connections.py", line 384, in check_error
    err.raise_mysql_exception(self._data)
  File "/usr/local/lib/python3.7/site-packages/pymysql/err.py", line 107, in raise_mysql_exception
    raise errorclass(errno, errval)
django.db.utils.InternalError: (1054, "Unknown column 'app_ckeiba_tran_systemstatus.Environment_id' in 'field list'")
[ERROR]	2020-04-20 09:51:19,487	module:log	django.request.log_response:228	Internal Server Error: /app_ckeiba/upload/
Traceback (most recent call last):
  File "/usr/local/lib/python3.7/site-packages/django/core/handlers/exception.py", line 34, in inner
    response = get_response(request)
  File "/usr/local/lib/python3.7/site-packages/django/core/handlers/base.py", line 126, in _get_response
    response = self.process_exception_by_middleware(e, request)
  File "/usr/local/lib/python3.7/site-packages/django/core/handlers/base.py", line 124, in _get_response
    response = wrapped_callback(request, *callback_args, **callback_kwargs)
  File "./app_ckeiba/views_csv.py", line 89, in upload
    return render(request, 'app_ckeiba/upload.html')
  File "/usr/local/lib/python3.7/site-packages/django/shortcuts.py", line 36, in render
    content = loader.render_to_string(template_name, context, request, using=using)
  File "/usr/local/lib/python3.7/site-packages/django/template/loader.py", line 62, in render_to_string
    return template.render(context, request)
  File "/usr/local/lib/python3.7/site-packages/django/template/backends/django.py", line 61, in render
    return self.template.render(context)
  File "/usr/local/lib/python3.7/site-packages/django/template/base.py", line 171, in render
    return self._render(context)
  File "/usr/local/lib/python3.7/site-packages/django/template/base.py", line 163, in _render
    return self.nodelist.render(context)
  File "/usr/local/lib/python3.7/site-packages/django/template/base.py", line 937, in render
    bit = node.render_annotated(context)
  File "/usr/local/lib/python3.7/site-packages/django/template/base.py", line 904, in render_annotated
    return self.render(context)
  File "/usr/local/lib/python3.7/site-packages/django/template/loader_tags.py", line 150, in render
    return compiled_parent._render(context)
  File "/usr/local/lib/python3.7/site-packages/django/template/base.py", line 163, in _render
    return self.nodelist.render(context)
  File "/usr/local/lib/python3.7/site-packages/django/template/base.py", line 937, in render
    bit = node.render_annotated(context)
  File "/usr/local/lib/python3.7/site-packages/django/template/base.py", line 904, in render_annotated
    return self.render(context)
  File "/usr/local/lib/python3.7/site-packages/django/template/loader_tags.py", line 62, in render
    result = block.nodelist.render(context)
  File "/usr/local/lib/python3.7/site-packages/django/template/base.py", line 937, in render
    bit = node.render_annotated(context)
  File "/usr/local/lib/python3.7/site-packages/django/template/base.py", line 904, in render_annotated
    return self.render(context)
  File "/usr/local/lib/python3.7/site-packages/django/template/defaulttags.py", line 442, in render
    url = reverse(view_name, args=args, kwargs=kwargs, current_app=current_app)
  File "/usr/local/lib/python3.7/site-packages/django/urls/base.py", line 90, in reverse
    return iri_to_uri(resolver._reverse_with_prefix(view, prefix, *args, **kwargs))
  File "/usr/local/lib/python3.7/site-packages/django/urls/resolvers.py", line 622, in _reverse_with_prefix
    raise NoReverseMatch(msg)
django.urls.exceptions.NoReverseMatch: Reverse for 'upload' not found. 'upload' is not a valid view function or pattern name.
[ERROR]	2020-04-20 09:56:52,498	module:log	django.request.log_response:228	Internal Server Error: /app_ckeiba/upload/
Traceback (most recent call last):
  File "/usr/local/lib/python3.7/site-packages/django/core/handlers/exception.py", line 34, in inner
    response = get_response(request)
  File "/usr/local/lib/python3.7/site-packages/django/core/handlers/base.py", line 126, in _get_response
    response = self.process_exception_by_middleware(e, request)
  File "/usr/local/lib/python3.7/site-packages/django/core/handlers/base.py", line 124, in _get_response
    response = wrapped_callback(request, *callback_args, **callback_kwargs)
  File "./app_ckeiba/views_csv.py", line 90, in upload
    return render(request, 'upload.html')
  File "/usr/local/lib/python3.7/site-packages/django/shortcuts.py", line 36, in render
    content = loader.render_to_string(template_name, context, request, using=using)
  File "/usr/local/lib/python3.7/site-packages/django/template/loader.py", line 61, in render_to_string
    template = get_template(template_name, using=using)
  File "/usr/local/lib/python3.7/site-packages/django/template/loader.py", line 19, in get_template
    raise TemplateDoesNotExist(template_name, chain=chain)
django.template.exceptions.TemplateDoesNotExist: upload.html
[ERROR]	2020-04-20 09:58:00,945	module:log	django.request.log_response:228	Internal Server Error: /app_ckeiba/upload/
Traceback (most recent call last):
  File "/usr/local/lib/python3.7/site-packages/django/core/handlers/exception.py", line 34, in inner
    response = get_response(request)
  File "/usr/local/lib/python3.7/site-packages/django/core/handlers/base.py", line 126, in _get_response
    response = self.process_exception_by_middleware(e, request)
  File "/usr/local/lib/python3.7/site-packages/django/core/handlers/base.py", line 124, in _get_response
    response = wrapped_callback(request, *callback_args, **callback_kwargs)
  File "./app_ckeiba/views_csv.py", line 90, in upload
    return render(request, 'app_ckeiba/upload.html')
  File "/usr/local/lib/python3.7/site-packages/django/shortcuts.py", line 36, in render
    content = loader.render_to_string(template_name, context, request, using=using)
  File "/usr/local/lib/python3.7/site-packages/django/template/loader.py", line 62, in render_to_string
    return template.render(context, request)
  File "/usr/local/lib/python3.7/site-packages/django/template/backends/django.py", line 61, in render
    return self.template.render(context)
  File "/usr/local/lib/python3.7/site-packages/django/template/base.py", line 171, in render
    return self._render(context)
  File "/usr/local/lib/python3.7/site-packages/django/template/base.py", line 163, in _render
    return self.nodelist.render(context)
  File "/usr/local/lib/python3.7/site-packages/django/template/base.py", line 937, in render
    bit = node.render_annotated(context)
  File "/usr/local/lib/python3.7/site-packages/django/template/base.py", line 904, in render_annotated
    return self.render(context)
  File "/usr/local/lib/python3.7/site-packages/django/template/loader_tags.py", line 150, in render
    return compiled_parent._render(context)
  File "/usr/local/lib/python3.7/site-packages/django/template/base.py", line 163, in _render
    return self.nodelist.render(context)
  File "/usr/local/lib/python3.7/site-packages/django/template/base.py", line 937, in render
    bit = node.render_annotated(context)
  File "/usr/local/lib/python3.7/site-packages/django/template/base.py", line 904, in render_annotated
    return self.render(context)
  File "/usr/local/lib/python3.7/site-packages/django/template/loader_tags.py", line 62, in render
    result = block.nodelist.render(context)
  File "/usr/local/lib/python3.7/site-packages/django/template/base.py", line 937, in render
    bit = node.render_annotated(context)
  File "/usr/local/lib/python3.7/site-packages/django/template/base.py", line 904, in render_annotated
    return self.render(context)
  File "/usr/local/lib/python3.7/site-packages/django/template/defaulttags.py", line 442, in render
    url = reverse(view_name, args=args, kwargs=kwargs, current_app=current_app)
  File "/usr/local/lib/python3.7/site-packages/django/urls/base.py", line 90, in reverse
    return iri_to_uri(resolver._reverse_with_prefix(view, prefix, *args, **kwargs))
  File "/usr/local/lib/python3.7/site-packages/django/urls/resolvers.py", line 622, in _reverse_with_prefix
    raise NoReverseMatch(msg)
django.urls.exceptions.NoReverseMatch: Reverse for 'upload' not found. 'upload' is not a valid view function or pattern name.
[WARNING]	2020-04-20 10:02:07,127	module:log	django.request.log_response:228	Not Found: /app_ckeiba/upload/
[WARNING]	2020-04-20 10:03:06,252	module:log	django.request.log_response:228	Not Found: /app_ckeiba/upload/
[WARNING]	2020-04-20 10:03:06,262	module:log	django.request.log_response:228	Not Found: /app_ckeiba/upload/
[WARNING]	2020-04-20 10:03:51,214	module:log	django.request.log_response:228	Not Found: /app_ckeiba/upload/
[WARNING]	2020-04-20 10:03:52,421	module:log	django.request.log_response:228	Not Found: /app_ckeiba/upload/
[ERROR]	2020-04-20 10:04:08,628	module:log	django.request.log_response:228	Internal Server Error: /app_ckeiba/upload/
Traceback (most recent call last):
  File "/usr/local/lib/python3.7/site-packages/django/core/handlers/exception.py", line 34, in inner
    response = get_response(request)
  File "/usr/local/lib/python3.7/site-packages/django/core/handlers/base.py", line 126, in _get_response
    response = self.process_exception_by_middleware(e, request)
  File "/usr/local/lib/python3.7/site-packages/django/core/handlers/base.py", line 124, in _get_response
    response = wrapped_callback(request, *callback_args, **callback_kwargs)
  File "./app_ckeiba/views_csv.py", line 90, in upload
    return render(request, 'app_ckeiba/upload.html')
  File "/usr/local/lib/python3.7/site-packages/django/shortcuts.py", line 36, in render
    content = loader.render_to_string(template_name, context, request, using=using)
  File "/usr/local/lib/python3.7/site-packages/django/template/loader.py", line 62, in render_to_string
    return template.render(context, request)
  File "/usr/local/lib/python3.7/site-packages/django/template/backends/django.py", line 61, in render
    return self.template.render(context)
  File "/usr/local/lib/python3.7/site-packages/django/template/base.py", line 171, in render
    return self._render(context)
  File "/usr/local/lib/python3.7/site-packages/django/template/base.py", line 163, in _render
    return self.nodelist.render(context)
  File "/usr/local/lib/python3.7/site-packages/django/template/base.py", line 937, in render
    bit = node.render_annotated(context)
  File "/usr/local/lib/python3.7/site-packages/django/template/base.py", line 904, in render_annotated
    return self.render(context)
  File "/usr/local/lib/python3.7/site-packages/django/template/loader_tags.py", line 150, in render
    return compiled_parent._render(context)
  File "/usr/local/lib/python3.7/site-packages/django/template/base.py", line 163, in _render
    return self.nodelist.render(context)
  File "/usr/local/lib/python3.7/site-packages/django/template/base.py", line 937, in render
    bit = node.render_annotated(context)
  File "/usr/local/lib/python3.7/site-packages/django/template/base.py", line 904, in render_annotated
    return self.render(context)
  File "/usr/local/lib/python3.7/site-packages/django/template/loader_tags.py", line 62, in render
    result = block.nodelist.render(context)
  File "/usr/local/lib/python3.7/site-packages/django/template/base.py", line 937, in render
    bit = node.render_annotated(context)
  File "/usr/local/lib/python3.7/site-packages/django/template/base.py", line 904, in render_annotated
    return self.render(context)
  File "/usr/local/lib/python3.7/site-packages/django/template/defaulttags.py", line 442, in render
    url = reverse(view_name, args=args, kwargs=kwargs, current_app=current_app)
  File "/usr/local/lib/python3.7/site-packages/django/urls/base.py", line 90, in reverse
    return iri_to_uri(resolver._reverse_with_prefix(view, prefix, *args, **kwargs))
  File "/usr/local/lib/python3.7/site-packages/django/urls/resolvers.py", line 622, in _reverse_with_prefix
    raise NoReverseMatch(msg)
django.urls.exceptions.NoReverseMatch: Reverse for 'upload' not found. 'upload' is not a valid view function or pattern name.
[ERROR]	2020-04-20 14:20:14,953	module:log	django.request.log_response:228	Internal Server Error: /app_ckeiba/
Traceback (most recent call last):
  File "/usr/local/lib/python3.7/site-packages/django/db/backends/utils.py", line 85, in _execute
    return self.cursor.execute(sql, params)
  File "/usr/local/lib/python3.7/site-packages/django/db/backends/mysql/base.py", line 71, in execute
    return self.cursor.execute(query, args)
  File "/usr/local/lib/python3.7/site-packages/pymysql/cursors.py", line 165, in execute
    result = self._query(query)
  File "/usr/local/lib/python3.7/site-packages/pymysql/cursors.py", line 321, in _query
    conn.query(q)
  File "/usr/local/lib/python3.7/site-packages/pymysql/connections.py", line 860, in query
    self._affected_rows = self._read_query_result(unbuffered=unbuffered)
  File "/usr/local/lib/python3.7/site-packages/pymysql/connections.py", line 1061, in _read_query_result
    result.read()
  File "/usr/local/lib/python3.7/site-packages/pymysql/connections.py", line 1349, in read
    first_packet = self.connection._read_packet()
  File "/usr/local/lib/python3.7/site-packages/pymysql/connections.py", line 1018, in _read_packet
    packet.check_error()
  File "/usr/local/lib/python3.7/site-packages/pymysql/connections.py", line 384, in check_error
    err.raise_mysql_exception(self._data)
  File "/usr/local/lib/python3.7/site-packages/pymysql/err.py", line 107, in raise_mysql_exception
    raise errorclass(errno, errval)
pymysql.err.InternalError: (1054, "Unknown column 'app_ckeiba_tran_systemstatus.Environment_id' in 'field list'")

The above exception was the direct cause of the following exception:

Traceback (most recent call last):
  File "/usr/local/lib/python3.7/site-packages/django/core/handlers/exception.py", line 34, in inner
    response = get_response(request)
  File "/usr/local/lib/python3.7/site-packages/django/core/handlers/base.py", line 126, in _get_response
    response = self.process_exception_by_middleware(e, request)
  File "/usr/local/lib/python3.7/site-packages/django/core/handlers/base.py", line 124, in _get_response
    response = wrapped_callback(request, *callback_args, **callback_kwargs)
  File "./app_ckeiba/views.py", line 27, in index
    tran_system = Tran_Systemstatus.objects.all().first() # ★ システム状態の1件目を見てるだけなので、ここは要検討
  File "/usr/local/lib/python3.7/site-packages/django/db/models/query.py", line 605, in first
    for obj in (self if self.ordered else self.order_by('pk'))[:1]:
  File "/usr/local/lib/python3.7/site-packages/django/db/models/query.py", line 268, in __iter__
    self._fetch_all()
  File "/usr/local/lib/python3.7/site-packages/django/db/models/query.py", line 1186, in _fetch_all
    self._result_cache = list(self._iterable_class(self))
  File "/usr/local/lib/python3.7/site-packages/django/db/models/query.py", line 54, in __iter__
    results = compiler.execute_sql(chunked_fetch=self.chunked_fetch, chunk_size=self.chunk_size)
  File "/usr/local/lib/python3.7/site-packages/django/db/models/sql/compiler.py", line 1065, in execute_sql
    cursor.execute(sql, params)
  File "/usr/local/lib/python3.7/site-packages/django/db/backends/utils.py", line 100, in execute
    return super().execute(sql, params)
  File "/usr/local/lib/python3.7/site-packages/django/db/backends/utils.py", line 68, in execute
    return self._execute_with_wrappers(sql, params, many=False, executor=self._execute)
  File "/usr/local/lib/python3.7/site-packages/django/db/backends/utils.py", line 77, in _execute_with_wrappers
    return executor(sql, params, many, context)
  File "/usr/local/lib/python3.7/site-packages/django/db/backends/utils.py", line 85, in _execute
    return self.cursor.execute(sql, params)
  File "/usr/local/lib/python3.7/site-packages/django/db/utils.py", line 89, in __exit__
    raise dj_exc_value.with_traceback(traceback) from exc_value
  File "/usr/local/lib/python3.7/site-packages/django/db/backends/utils.py", line 85, in _execute
    return self.cursor.execute(sql, params)
  File "/usr/local/lib/python3.7/site-packages/django/db/backends/mysql/base.py", line 71, in execute
    return self.cursor.execute(query, args)
  File "/usr/local/lib/python3.7/site-packages/pymysql/cursors.py", line 165, in execute
    result = self._query(query)
  File "/usr/local/lib/python3.7/site-packages/pymysql/cursors.py", line 321, in _query
    conn.query(q)
  File "/usr/local/lib/python3.7/site-packages/pymysql/connections.py", line 860, in query
    self._affected_rows = self._read_query_result(unbuffered=unbuffered)
  File "/usr/local/lib/python3.7/site-packages/pymysql/connections.py", line 1061, in _read_query_result
    result.read()
  File "/usr/local/lib/python3.7/site-packages/pymysql/connections.py", line 1349, in read
    first_packet = self.connection._read_packet()
  File "/usr/local/lib/python3.7/site-packages/pymysql/connections.py", line 1018, in _read_packet
    packet.check_error()
  File "/usr/local/lib/python3.7/site-packages/pymysql/connections.py", line 384, in check_error
    err.raise_mysql_exception(self._data)
  File "/usr/local/lib/python3.7/site-packages/pymysql/err.py", line 107, in raise_mysql_exception
    raise errorclass(errno, errval)
django.db.utils.InternalError: (1054, "Unknown column 'app_ckeiba_tran_systemstatus.Environment_id' in 'field list'")
[ERROR]	2020-04-20 14:20:21,346	module:log	django.request.log_response:228	Internal Server Error: /app_ckeiba/upload/
Traceback (most recent call last):
  File "/usr/local/lib/python3.7/site-packages/django/core/handlers/exception.py", line 34, in inner
    response = get_response(request)
  File "/usr/local/lib/python3.7/site-packages/django/core/handlers/base.py", line 126, in _get_response
    response = self.process_exception_by_middleware(e, request)
  File "/usr/local/lib/python3.7/site-packages/django/core/handlers/base.py", line 124, in _get_response
    response = wrapped_callback(request, *callback_args, **callback_kwargs)
  File "./app_ckeiba/views_csv.py", line 90, in upload
    return render(request, 'app_ckeiba/upload.html')
  File "/usr/local/lib/python3.7/site-packages/django/shortcuts.py", line 36, in render
    content = loader.render_to_string(template_name, context, request, using=using)
  File "/usr/local/lib/python3.7/site-packages/django/template/loader.py", line 62, in render_to_string
    return template.render(context, request)
  File "/usr/local/lib/python3.7/site-packages/django/template/backends/django.py", line 61, in render
    return self.template.render(context)
  File "/usr/local/lib/python3.7/site-packages/django/template/base.py", line 171, in render
    return self._render(context)
  File "/usr/local/lib/python3.7/site-packages/django/template/base.py", line 163, in _render
    return self.nodelist.render(context)
  File "/usr/local/lib/python3.7/site-packages/django/template/base.py", line 937, in render
    bit = node.render_annotated(context)
  File "/usr/local/lib/python3.7/site-packages/django/template/base.py", line 904, in render_annotated
    return self.render(context)
  File "/usr/local/lib/python3.7/site-packages/django/template/loader_tags.py", line 150, in render
    return compiled_parent._render(context)
  File "/usr/local/lib/python3.7/site-packages/django/template/base.py", line 163, in _render
    return self.nodelist.render(context)
  File "/usr/local/lib/python3.7/site-packages/django/template/base.py", line 937, in render
    bit = node.render_annotated(context)
  File "/usr/local/lib/python3.7/site-packages/django/template/base.py", line 904, in render_annotated
    return self.render(context)
  File "/usr/local/lib/python3.7/site-packages/django/template/loader_tags.py", line 62, in render
    result = block.nodelist.render(context)
  File "/usr/local/lib/python3.7/site-packages/django/template/base.py", line 937, in render
    bit = node.render_annotated(context)
  File "/usr/local/lib/python3.7/site-packages/django/template/base.py", line 904, in render_annotated
    return self.render(context)
  File "/usr/local/lib/python3.7/site-packages/django/template/defaulttags.py", line 442, in render
    url = reverse(view_name, args=args, kwargs=kwargs, current_app=current_app)
  File "/usr/local/lib/python3.7/site-packages/django/urls/base.py", line 90, in reverse
    return iri_to_uri(resolver._reverse_with_prefix(view, prefix, *args, **kwargs))
  File "/usr/local/lib/python3.7/site-packages/django/urls/resolvers.py", line 622, in _reverse_with_prefix
    raise NoReverseMatch(msg)
django.urls.exceptions.NoReverseMatch: Reverse for 'upload' not found. 'upload' is not a valid view function or pattern name.
[ERROR]	2020-04-20 14:26:27,938	module:log	django.request.log_response:228	Internal Server Error: /app_ckeiba/upload/
Traceback (most recent call last):
  File "/usr/local/lib/python3.7/site-packages/django/core/handlers/exception.py", line 34, in inner
    response = get_response(request)
  File "/usr/local/lib/python3.7/site-packages/django/core/handlers/base.py", line 111, in _get_response
    resolver_match = resolver.resolve(request.path_info)
  File "/usr/local/lib/python3.7/site-packages/django/urls/resolvers.py", line 491, in resolve
    for pattern in self.url_patterns:
  File "/usr/local/lib/python3.7/site-packages/django/utils/functional.py", line 37, in __get__
    res = instance.__dict__[self.name] = self.func(instance)
  File "/usr/local/lib/python3.7/site-packages/django/urls/resolvers.py", line 533, in url_patterns
    patterns = getattr(self.urlconf_module, "urlpatterns", self.urlconf_module)
  File "/usr/local/lib/python3.7/site-packages/django/utils/functional.py", line 37, in __get__
    res = instance.__dict__[self.name] = self.func(instance)
  File "/usr/local/lib/python3.7/site-packages/django/urls/resolvers.py", line 526, in urlconf_module
    return import_module(self.urlconf_name)
  File "/usr/local/lib/python3.7/importlib/__init__.py", line 127, in import_module
    return _bootstrap._gcd_import(name[level:], package, level)
  File "<frozen importlib._bootstrap>", line 1006, in _gcd_import
  File "<frozen importlib._bootstrap>", line 983, in _find_and_load
  File "<frozen importlib._bootstrap>", line 967, in _find_and_load_unlocked
  File "<frozen importlib._bootstrap>", line 677, in _load_unlocked
  File "<frozen importlib._bootstrap_external>", line 728, in exec_module
  File "<frozen importlib._bootstrap>", line 219, in _call_with_frames_removed
  File "./prj_sports/urls.py", line 8, in <module>
    path('app_ckeiba/', include('app_ckeiba.urls')),
  File "/usr/local/lib/python3.7/site-packages/django/urls/conf.py", line 34, in include
    urlconf_module = import_module(urlconf_module)
  File "/usr/local/lib/python3.7/importlib/__init__.py", line 127, in import_module
    return _bootstrap._gcd_import(name[level:], package, level)
  File "<frozen importlib._bootstrap>", line 1006, in _gcd_import
  File "<frozen importlib._bootstrap>", line 983, in _find_and_load
  File "<frozen importlib._bootstrap>", line 967, in _find_and_load_unlocked
  File "<frozen importlib._bootstrap>", line 677, in _load_unlocked
  File "<frozen importlib._bootstrap_external>", line 728, in exec_module
  File "<frozen importlib._bootstrap>", line 219, in _call_with_frames_removed
  File "./app_ckeiba/urls.py", line 2, in <module>
    from . import views
  File "./app_ckeiba/views.py", line 13, in <module>
    from .views_csv import *
  File "./app_ckeiba/views_csv.py", line 86
    return render(request, {% url 'app_ckeiba:upload' %})
                            ^
SyntaxError: invalid syntax
[ERROR]	2020-04-20 14:29:26,495	module:log	django.request.log_response:228	Internal Server Error: /app_ckeiba/upload/
Traceback (most recent call last):
  File "/usr/local/lib/python3.7/site-packages/django/core/handlers/exception.py", line 34, in inner
    response = get_response(request)
  File "/usr/local/lib/python3.7/site-packages/django/core/handlers/base.py", line 111, in _get_response
    resolver_match = resolver.resolve(request.path_info)
  File "/usr/local/lib/python3.7/site-packages/django/urls/resolvers.py", line 491, in resolve
    for pattern in self.url_patterns:
  File "/usr/local/lib/python3.7/site-packages/django/utils/functional.py", line 37, in __get__
    res = instance.__dict__[self.name] = self.func(instance)
  File "/usr/local/lib/python3.7/site-packages/django/urls/resolvers.py", line 533, in url_patterns
    patterns = getattr(self.urlconf_module, "urlpatterns", self.urlconf_module)
  File "/usr/local/lib/python3.7/site-packages/django/utils/functional.py", line 37, in __get__
    res = instance.__dict__[self.name] = self.func(instance)
  File "/usr/local/lib/python3.7/site-packages/django/urls/resolvers.py", line 526, in urlconf_module
    return import_module(self.urlconf_name)
  File "/usr/local/lib/python3.7/importlib/__init__.py", line 127, in import_module
    return _bootstrap._gcd_import(name[level:], package, level)
  File "<frozen importlib._bootstrap>", line 1006, in _gcd_import
  File "<frozen importlib._bootstrap>", line 983, in _find_and_load
  File "<frozen importlib._bootstrap>", line 967, in _find_and_load_unlocked
  File "<frozen importlib._bootstrap>", line 677, in _load_unlocked
  File "<frozen importlib._bootstrap_external>", line 728, in exec_module
  File "<frozen importlib._bootstrap>", line 219, in _call_with_frames_removed
  File "./prj_sports/urls.py", line 8, in <module>
    path('app_ckeiba/', include('app_ckeiba.urls')),
  File "/usr/local/lib/python3.7/site-packages/django/urls/conf.py", line 34, in include
    urlconf_module = import_module(urlconf_module)
  File "/usr/local/lib/python3.7/importlib/__init__.py", line 127, in import_module
    return _bootstrap._gcd_import(name[level:], package, level)
  File "<frozen importlib._bootstrap>", line 1006, in _gcd_import
  File "<frozen importlib._bootstrap>", line 983, in _find_and_load
  File "<frozen importlib._bootstrap>", line 967, in _find_and_load_unlocked
  File "<frozen importlib._bootstrap>", line 677, in _load_unlocked
  File "<frozen importlib._bootstrap_external>", line 728, in exec_module
  File "<frozen importlib._bootstrap>", line 219, in _call_with_frames_removed
  File "./app_ckeiba/urls.py", line 2, in <module>
    from . import views
  File "./app_ckeiba/views.py", line 13, in <module>
    from .views_csv import *
  File "./app_ckeiba/views_csv.py", line 86
    return render(request, {% url 'app_ckeiba:upload' %})
                            ^
SyntaxError: invalid syntax
[ERROR]	2020-04-20 14:29:27,847	module:log	django.request.log_response:228	Internal Server Error: /app_ckeiba/upload/
Traceback (most recent call last):
  File "/usr/local/lib/python3.7/site-packages/django/core/handlers/exception.py", line 34, in inner
    response = get_response(request)
  File "/usr/local/lib/python3.7/site-packages/django/core/handlers/base.py", line 111, in _get_response
    resolver_match = resolver.resolve(request.path_info)
  File "/usr/local/lib/python3.7/site-packages/django/urls/resolvers.py", line 491, in resolve
    for pattern in self.url_patterns:
  File "/usr/local/lib/python3.7/site-packages/django/utils/functional.py", line 37, in __get__
    res = instance.__dict__[self.name] = self.func(instance)
  File "/usr/local/lib/python3.7/site-packages/django/urls/resolvers.py", line 533, in url_patterns
    patterns = getattr(self.urlconf_module, "urlpatterns", self.urlconf_module)
  File "/usr/local/lib/python3.7/site-packages/django/utils/functional.py", line 37, in __get__
    res = instance.__dict__[self.name] = self.func(instance)
  File "/usr/local/lib/python3.7/site-packages/django/urls/resolvers.py", line 526, in urlconf_module
    return import_module(self.urlconf_name)
  File "/usr/local/lib/python3.7/importlib/__init__.py", line 127, in import_module
    return _bootstrap._gcd_import(name[level:], package, level)
  File "<frozen importlib._bootstrap>", line 1006, in _gcd_import
  File "<frozen importlib._bootstrap>", line 983, in _find_and_load
  File "<frozen importlib._bootstrap>", line 967, in _find_and_load_unlocked
  File "<frozen importlib._bootstrap>", line 677, in _load_unlocked
  File "<frozen importlib._bootstrap_external>", line 728, in exec_module
  File "<frozen importlib._bootstrap>", line 219, in _call_with_frames_removed
  File "./prj_sports/urls.py", line 8, in <module>
    path('app_ckeiba/', include('app_ckeiba.urls')),
  File "/usr/local/lib/python3.7/site-packages/django/urls/conf.py", line 34, in include
    urlconf_module = import_module(urlconf_module)
  File "/usr/local/lib/python3.7/importlib/__init__.py", line 127, in import_module
    return _bootstrap._gcd_import(name[level:], package, level)
  File "<frozen importlib._bootstrap>", line 1006, in _gcd_import
  File "<frozen importlib._bootstrap>", line 983, in _find_and_load
  File "<frozen importlib._bootstrap>", line 967, in _find_and_load_unlocked
  File "<frozen importlib._bootstrap>", line 677, in _load_unlocked
  File "<frozen importlib._bootstrap_external>", line 728, in exec_module
  File "<frozen importlib._bootstrap>", line 219, in _call_with_frames_removed
  File "./app_ckeiba/urls.py", line 2, in <module>
    from . import views
  File "./app_ckeiba/views.py", line 13, in <module>
    from .views_csv import *
  File "./app_ckeiba/views_csv.py", line 86
    return render(request, {% url 'app_ckeiba:upload' %})
                            ^
SyntaxError: invalid syntax
[ERROR]	2020-04-20 14:30:21,462	module:log	django.request.log_response:228	Internal Server Error: /app_ckeiba/upload/
Traceback (most recent call last):
  File "/usr/local/lib/python3.7/site-packages/django/core/handlers/exception.py", line 34, in inner
    response = get_response(request)
  File "/usr/local/lib/python3.7/site-packages/django/core/handlers/base.py", line 111, in _get_response
    resolver_match = resolver.resolve(request.path_info)
  File "/usr/local/lib/python3.7/site-packages/django/urls/resolvers.py", line 491, in resolve
    for pattern in self.url_patterns:
  File "/usr/local/lib/python3.7/site-packages/django/utils/functional.py", line 37, in __get__
    res = instance.__dict__[self.name] = self.func(instance)
  File "/usr/local/lib/python3.7/site-packages/django/urls/resolvers.py", line 533, in url_patterns
    patterns = getattr(self.urlconf_module, "urlpatterns", self.urlconf_module)
  File "/usr/local/lib/python3.7/site-packages/django/utils/functional.py", line 37, in __get__
    res = instance.__dict__[self.name] = self.func(instance)
  File "/usr/local/lib/python3.7/site-packages/django/urls/resolvers.py", line 526, in urlconf_module
    return import_module(self.urlconf_name)
  File "/usr/local/lib/python3.7/importlib/__init__.py", line 127, in import_module
    return _bootstrap._gcd_import(name[level:], package, level)
  File "<frozen importlib._bootstrap>", line 1006, in _gcd_import
  File "<frozen importlib._bootstrap>", line 983, in _find_and_load
  File "<frozen importlib._bootstrap>", line 967, in _find_and_load_unlocked
  File "<frozen importlib._bootstrap>", line 677, in _load_unlocked
  File "<frozen importlib._bootstrap_external>", line 728, in exec_module
  File "<frozen importlib._bootstrap>", line 219, in _call_with_frames_removed
  File "./prj_sports/urls.py", line 8, in <module>
    path('app_ckeiba/', include('app_ckeiba.urls')),
  File "/usr/local/lib/python3.7/site-packages/django/urls/conf.py", line 34, in include
    urlconf_module = import_module(urlconf_module)
  File "/usr/local/lib/python3.7/importlib/__init__.py", line 127, in import_module
    return _bootstrap._gcd_import(name[level:], package, level)
  File "<frozen importlib._bootstrap>", line 1006, in _gcd_import
  File "<frozen importlib._bootstrap>", line 983, in _find_and_load
  File "<frozen importlib._bootstrap>", line 967, in _find_and_load_unlocked
  File "<frozen importlib._bootstrap>", line 677, in _load_unlocked
  File "<frozen importlib._bootstrap_external>", line 728, in exec_module
  File "<frozen importlib._bootstrap>", line 219, in _call_with_frames_removed
  File "./app_ckeiba/urls.py", line 2, in <module>
    from . import views
  File "./app_ckeiba/views.py", line 13, in <module>
    from .views_csv import *
  File "./app_ckeiba/views_csv.py", line 86
    return render(request, {% url 'app_ckeiba:upload' %})
                            ^
SyntaxError: invalid syntax
[WARNING]	2020-04-20 14:30:35,193	module:log	django.request.log_response:228	Not Found: /app_ckeiba/upload/
[WARNING]	2020-04-20 14:31:07,724	module:log	django.request.log_response:228	Not Found: /app_ckeiba/upload/
[WARNING]	2020-04-20 14:31:11,078	module:log	django.request.log_response:228	Not Found: /app_ckeiba/upload/
[ERROR]	2020-04-20 14:31:40,160	module:log	django.request.log_response:228	Internal Server Error: /app_ckeiba/upload/
Traceback (most recent call last):
  File "/usr/local/lib/python3.7/site-packages/django/core/handlers/exception.py", line 34, in inner
    response = get_response(request)
  File "/usr/local/lib/python3.7/site-packages/django/core/handlers/base.py", line 126, in _get_response
    response = self.process_exception_by_middleware(e, request)
  File "/usr/local/lib/python3.7/site-packages/django/core/handlers/base.py", line 124, in _get_response
    response = wrapped_callback(request, *callback_args, **callback_kwargs)
  File "./app_ckeiba/views_csv.py", line 89, in upload
    return render(request, 'app_ckeiba/upload.html')
  File "/usr/local/lib/python3.7/site-packages/django/shortcuts.py", line 36, in render
    content = loader.render_to_string(template_name, context, request, using=using)
  File "/usr/local/lib/python3.7/site-packages/django/template/loader.py", line 62, in render_to_string
    return template.render(context, request)
  File "/usr/local/lib/python3.7/site-packages/django/template/backends/django.py", line 61, in render
    return self.template.render(context)
  File "/usr/local/lib/python3.7/site-packages/django/template/base.py", line 171, in render
    return self._render(context)
  File "/usr/local/lib/python3.7/site-packages/django/template/base.py", line 163, in _render
    return self.nodelist.render(context)
  File "/usr/local/lib/python3.7/site-packages/django/template/base.py", line 937, in render
    bit = node.render_annotated(context)
  File "/usr/local/lib/python3.7/site-packages/django/template/base.py", line 904, in render_annotated
    return self.render(context)
  File "/usr/local/lib/python3.7/site-packages/django/template/loader_tags.py", line 150, in render
    return compiled_parent._render(context)
  File "/usr/local/lib/python3.7/site-packages/django/template/base.py", line 163, in _render
    return self.nodelist.render(context)
  File "/usr/local/lib/python3.7/site-packages/django/template/base.py", line 937, in render
    bit = node.render_annotated(context)
  File "/usr/local/lib/python3.7/site-packages/django/template/base.py", line 904, in render_annotated
    return self.render(context)
  File "/usr/local/lib/python3.7/site-packages/django/template/loader_tags.py", line 62, in render
    result = block.nodelist.render(context)
  File "/usr/local/lib/python3.7/site-packages/django/template/base.py", line 937, in render
    bit = node.render_annotated(context)
  File "/usr/local/lib/python3.7/site-packages/django/template/base.py", line 904, in render_annotated
    return self.render(context)
  File "/usr/local/lib/python3.7/site-packages/django/template/defaulttags.py", line 442, in render
    url = reverse(view_name, args=args, kwargs=kwargs, current_app=current_app)
  File "/usr/local/lib/python3.7/site-packages/django/urls/base.py", line 90, in reverse
    return iri_to_uri(resolver._reverse_with_prefix(view, prefix, *args, **kwargs))
  File "/usr/local/lib/python3.7/site-packages/django/urls/resolvers.py", line 622, in _reverse_with_prefix
    raise NoReverseMatch(msg)
django.urls.exceptions.NoReverseMatch: Reverse for 'upload' not found. 'upload' is not a valid view function or pattern name.
[ERROR]	2020-04-20 14:39:50,723	module:log	django.request.log_response:228	Internal Server Error: /app_ckeiba/upload/
Traceback (most recent call last):
  File "/usr/local/lib/python3.7/site-packages/django/db/models/query.py", line 486, in get_or_create
    return self.get(**lookup), False
  File "/usr/local/lib/python3.7/site-packages/django/db/models/query.py", line 399, in get
    self.model._meta.object_name
app_ckeiba.models_csv.Schedule_BA7.DoesNotExist: Schedule_BA7 matching query does not exist.

During handling of the above exception, another exception occurred:

Traceback (most recent call last):
  File "/usr/local/lib/python3.7/site-packages/django/db/backends/utils.py", line 85, in _execute
    return self.cursor.execute(sql, params)
  File "/usr/local/lib/python3.7/site-packages/django/db/backends/mysql/base.py", line 71, in execute
    return self.cursor.execute(query, args)
  File "/usr/local/lib/python3.7/site-packages/pymysql/cursors.py", line 165, in execute
    result = self._query(query)
  File "/usr/local/lib/python3.7/site-packages/pymysql/cursors.py", line 321, in _query
    conn.query(q)
  File "/usr/local/lib/python3.7/site-packages/pymysql/connections.py", line 860, in query
    self._affected_rows = self._read_query_result(unbuffered=unbuffered)
  File "/usr/local/lib/python3.7/site-packages/pymysql/connections.py", line 1061, in _read_query_result
    result.read()
  File "/usr/local/lib/python3.7/site-packages/pymysql/connections.py", line 1349, in read
    first_packet = self.connection._read_packet()
  File "/usr/local/lib/python3.7/site-packages/pymysql/connections.py", line 1018, in _read_packet
    packet.check_error()
  File "/usr/local/lib/python3.7/site-packages/pymysql/connections.py", line 384, in check_error
    err.raise_mysql_exception(self._data)
  File "/usr/local/lib/python3.7/site-packages/pymysql/err.py", line 107, in raise_mysql_exception
    raise errorclass(errno, errval)
pymysql.err.DataError: (1406, "Data too long for column 'Data_ID' at row 1")

The above exception was the direct cause of the following exception:

Traceback (most recent call last):
  File "/usr/local/lib/python3.7/site-packages/django/core/handlers/exception.py", line 34, in inner
    response = get_response(request)
  File "/usr/local/lib/python3.7/site-packages/django/core/handlers/base.py", line 126, in _get_response
    response = self.process_exception_by_middleware(e, request)
  File "/usr/local/lib/python3.7/site-packages/django/core/handlers/base.py", line 124, in _get_response
    response = wrapped_callback(request, *callback_args, **callback_kwargs)
  File "./app_ckeiba/views_csv.py", line 20, in upload
    BA7, created = Schedule_BA7.objects.get_or_create(Data_ID=line[1])
  File "/usr/local/lib/python3.7/site-packages/django/db/models/manager.py", line 82, in manager_method
    return getattr(self.get_queryset(), name)(*args, **kwargs)
  File "/usr/local/lib/python3.7/site-packages/django/db/models/query.py", line 488, in get_or_create
    return self._create_object_from_params(lookup, params)
  File "/usr/local/lib/python3.7/site-packages/django/db/models/query.py", line 522, in _create_object_from_params
    obj = self.create(**params)
  File "/usr/local/lib/python3.7/site-packages/django/db/models/query.py", line 413, in create
    obj.save(force_insert=True, using=self.db)
  File "/usr/local/lib/python3.7/site-packages/django/db/models/base.py", line 718, in save
    force_update=force_update, update_fields=update_fields)
  File "/usr/local/lib/python3.7/site-packages/django/db/models/base.py", line 748, in save_base
    updated = self._save_table(raw, cls, force_insert, force_update, using, update_fields)
  File "/usr/local/lib/python3.7/site-packages/django/db/models/base.py", line 831, in _save_table
    result = self._do_insert(cls._base_manager, using, fields, update_pk, raw)
  File "/usr/local/lib/python3.7/site-packages/django/db/models/base.py", line 869, in _do_insert
    using=using, raw=raw)
  File "/usr/local/lib/python3.7/site-packages/django/db/models/manager.py", line 82, in manager_method
    return getattr(self.get_queryset(), name)(*args, **kwargs)
  File "/usr/local/lib/python3.7/site-packages/django/db/models/query.py", line 1136, in _insert
    return query.get_compiler(using=using).execute_sql(return_id)
  File "/usr/local/lib/python3.7/site-packages/django/db/models/sql/compiler.py", line 1289, in execute_sql
    cursor.execute(sql, params)
  File "/usr/local/lib/python3.7/site-packages/django/db/backends/utils.py", line 100, in execute
    return super().execute(sql, params)
  File "/usr/local/lib/python3.7/site-packages/django/db/backends/utils.py", line 68, in execute
    return self._execute_with_wrappers(sql, params, many=False, executor=self._execute)
  File "/usr/local/lib/python3.7/site-packages/django/db/backends/utils.py", line 77, in _execute_with_wrappers
    return executor(sql, params, many, context)
  File "/usr/local/lib/python3.7/site-packages/django/db/backends/utils.py", line 85, in _execute
    return self.cursor.execute(sql, params)
  File "/usr/local/lib/python3.7/site-packages/django/db/utils.py", line 89, in __exit__
    raise dj_exc_value.with_traceback(traceback) from exc_value
  File "/usr/local/lib/python3.7/site-packages/django/db/backends/utils.py", line 85, in _execute
    return self.cursor.execute(sql, params)
  File "/usr/local/lib/python3.7/site-packages/django/db/backends/mysql/base.py", line 71, in execute
    return self.cursor.execute(query, args)
  File "/usr/local/lib/python3.7/site-packages/pymysql/cursors.py", line 165, in execute
    result = self._query(query)
  File "/usr/local/lib/python3.7/site-packages/pymysql/cursors.py", line 321, in _query
    conn.query(q)
  File "/usr/local/lib/python3.7/site-packages/pymysql/connections.py", line 860, in query
    self._affected_rows = self._read_query_result(unbuffered=unbuffered)
  File "/usr/local/lib/python3.7/site-packages/pymysql/connections.py", line 1061, in _read_query_result
    result.read()
  File "/usr/local/lib/python3.7/site-packages/pymysql/connections.py", line 1349, in read
    first_packet = self.connection._read_packet()
  File "/usr/local/lib/python3.7/site-packages/pymysql/connections.py", line 1018, in _read_packet
    packet.check_error()
  File "/usr/local/lib/python3.7/site-packages/pymysql/connections.py", line 384, in check_error
    err.raise_mysql_exception(self._data)
  File "/usr/local/lib/python3.7/site-packages/pymysql/err.py", line 107, in raise_mysql_exception
    raise errorclass(errno, errval)
django.db.utils.DataError: (1406, "Data too long for column 'Data_ID' at row 1")
[WARNING]	2020-04-20 16:39:02,944	module:log	django.request.log_response:228	Not Found: /favicon.ico
[WARNING]	2020-04-20 16:45:07,284	module:log	django.request.log_response:228	Not Found: /favicon.ico
[WARNING]	2020-04-21 10:15:50,336	module:log	django.request.log_response:228	Not Found: /
[WARNING]	2020-04-21 10:15:50,357	module:log	django.request.log_response:228	Not Found: /apple-touch-icon-precomposed.png
[WARNING]	2020-04-21 10:15:50,359	module:log	django.request.log_response:228	Not Found: /favicon.ico
[WARNING]	2020-04-21 10:15:50,362	module:log	django.request.log_response:228	Not Found: /apple-touch-icon.png
[WARNING]	2020-04-21 10:16:07,997	module:log	django.request.log_response:228	Not Found: /
[WARNING]	2020-04-21 10:16:19,045	module:log	django.request.log_response:228	Not Found: /favicon.ico
[WARNING]	2020-04-21 10:16:26,472	module:log	django.request.log_response:228	Not Found: /favicon.ico
[WARNING]	2020-04-21 10:16:49,683	module:log	django.request.log_response:228	Not Found: /favicon.ico
[WARNING]	2020-04-21 10:16:50,776	module:log	django.request.log_response:228	Not Found: /favicon.ico
[WARNING]	2020-04-21 10:17:04,481	module:log	django.request.log_response:228	Not Found: /favicon.ico
[WARNING]	2020-04-21 10:17:06,073	module:log	django.request.log_response:228	Not Found: /favicon.ico
[WARNING]	2020-04-21 10:17:11,580	module:log	django.request.log_response:228	Not Found: /favicon.ico
[WARNING]	2020-04-21 10:17:15,285	module:log	django.request.log_response:228	Not Found: /favicon.ico
[WARNING]	2020-04-21 10:17:36,999	module:log	django.request.log_response:228	Not Found: /favicon.ico
[ERROR]	2020-04-21 10:17:41,366	module:log	django.request.log_response:228	Internal Server Error: /admin/app_autorace/trn_outside_track/
Traceback (most recent call last):
  File "/usr/local/lib/python3.7/site-packages/django/db/backends/utils.py", line 85, in _execute
    return self.cursor.execute(sql, params)
  File "/usr/local/lib/python3.7/site-packages/django/db/backends/mysql/base.py", line 71, in execute
    return self.cursor.execute(query, args)
  File "/usr/local/lib/python3.7/site-packages/pymysql/cursors.py", line 165, in execute
    result = self._query(query)
  File "/usr/local/lib/python3.7/site-packages/pymysql/cursors.py", line 321, in _query
    conn.query(q)
  File "/usr/local/lib/python3.7/site-packages/pymysql/connections.py", line 860, in query
    self._affected_rows = self._read_query_result(unbuffered=unbuffered)
  File "/usr/local/lib/python3.7/site-packages/pymysql/connections.py", line 1061, in _read_query_result
    result.read()
  File "/usr/local/lib/python3.7/site-packages/pymysql/connections.py", line 1349, in read
    first_packet = self.connection._read_packet()
  File "/usr/local/lib/python3.7/site-packages/pymysql/connections.py", line 1018, in _read_packet
    packet.check_error()
  File "/usr/local/lib/python3.7/site-packages/pymysql/connections.py", line 384, in check_error
    err.raise_mysql_exception(self._data)
  File "/usr/local/lib/python3.7/site-packages/pymysql/err.py", line 107, in raise_mysql_exception
    raise errorclass(errno, errval)
pymysql.err.InternalError: (1054, "Unknown column 'app_autorace_trn_outside_track.Track_code' in 'field list'")

The above exception was the direct cause of the following exception:

Traceback (most recent call last):
  File "/usr/local/lib/python3.7/site-packages/django/core/handlers/exception.py", line 34, in inner
    response = get_response(request)
  File "/usr/local/lib/python3.7/site-packages/django/core/handlers/base.py", line 126, in _get_response
    response = self.process_exception_by_middleware(e, request)
  File "/usr/local/lib/python3.7/site-packages/django/core/handlers/base.py", line 124, in _get_response
    response = wrapped_callback(request, *callback_args, **callback_kwargs)
  File "/usr/local/lib/python3.7/site-packages/django/contrib/admin/options.py", line 604, in wrapper
    return self.admin_site.admin_view(view)(*args, **kwargs)
  File "/usr/local/lib/python3.7/site-packages/django/utils/decorators.py", line 142, in _wrapped_view
    response = view_func(request, *args, **kwargs)
  File "/usr/local/lib/python3.7/site-packages/django/views/decorators/cache.py", line 44, in _wrapped_view_func
    response = view_func(request, *args, **kwargs)
  File "/usr/local/lib/python3.7/site-packages/django/contrib/admin/sites.py", line 223, in inner
    return view(request, *args, **kwargs)
  File "/usr/local/lib/python3.7/site-packages/django/utils/decorators.py", line 45, in _wrapper
    return bound_method(*args, **kwargs)
  File "/usr/local/lib/python3.7/site-packages/django/utils/decorators.py", line 142, in _wrapped_view
    response = view_func(request, *args, **kwargs)
  File "/usr/local/lib/python3.7/site-packages/django/contrib/admin/options.py", line 1793, in changelist_view
    'selection_note': _('0 of %(cnt)s selected') % {'cnt': len(cl.result_list)},
  File "/usr/local/lib/python3.7/site-packages/django/db/models/query.py", line 250, in __len__
    self._fetch_all()
  File "/usr/local/lib/python3.7/site-packages/django/db/models/query.py", line 1186, in _fetch_all
    self._result_cache = list(self._iterable_class(self))
  File "/usr/local/lib/python3.7/site-packages/django/db/models/query.py", line 54, in __iter__
    results = compiler.execute_sql(chunked_fetch=self.chunked_fetch, chunk_size=self.chunk_size)
  File "/usr/local/lib/python3.7/site-packages/django/db/models/sql/compiler.py", line 1065, in execute_sql
    cursor.execute(sql, params)
  File "/usr/local/lib/python3.7/site-packages/django/db/backends/utils.py", line 100, in execute
    return super().execute(sql, params)
  File "/usr/local/lib/python3.7/site-packages/django/db/backends/utils.py", line 68, in execute
    return self._execute_with_wrappers(sql, params, many=False, executor=self._execute)
  File "/usr/local/lib/python3.7/site-packages/django/db/backends/utils.py", line 77, in _execute_with_wrappers
    return executor(sql, params, many, context)
  File "/usr/local/lib/python3.7/site-packages/django/db/backends/utils.py", line 85, in _execute
    return self.cursor.execute(sql, params)
  File "/usr/local/lib/python3.7/site-packages/django/db/utils.py", line 89, in __exit__
    raise dj_exc_value.with_traceback(traceback) from exc_value
  File "/usr/local/lib/python3.7/site-packages/django/db/backends/utils.py", line 85, in _execute
    return self.cursor.execute(sql, params)
  File "/usr/local/lib/python3.7/site-packages/django/db/backends/mysql/base.py", line 71, in execute
    return self.cursor.execute(query, args)
  File "/usr/local/lib/python3.7/site-packages/pymysql/cursors.py", line 165, in execute
    result = self._query(query)
  File "/usr/local/lib/python3.7/site-packages/pymysql/cursors.py", line 321, in _query
    conn.query(q)
  File "/usr/local/lib/python3.7/site-packages/pymysql/connections.py", line 860, in query
    self._affected_rows = self._read_query_result(unbuffered=unbuffered)
  File "/usr/local/lib/python3.7/site-packages/pymysql/connections.py", line 1061, in _read_query_result
    result.read()
  File "/usr/local/lib/python3.7/site-packages/pymysql/connections.py", line 1349, in read
    first_packet = self.connection._read_packet()
  File "/usr/local/lib/python3.7/site-packages/pymysql/connections.py", line 1018, in _read_packet
    packet.check_error()
  File "/usr/local/lib/python3.7/site-packages/pymysql/connections.py", line 384, in check_error
    err.raise_mysql_exception(self._data)
  File "/usr/local/lib/python3.7/site-packages/pymysql/err.py", line 107, in raise_mysql_exception
    raise errorclass(errno, errval)
django.db.utils.InternalError: (1054, "Unknown column 'app_autorace_trn_outside_track.Track_code' in 'field list'")
[WARNING]	2020-04-21 10:17:41,467	module:log	django.request.log_response:228	Not Found: /favicon.ico
[ERROR]	2020-04-21 10:17:44,295	module:log	django.request.log_response:228	Internal Server Error: /admin/app_autorace/trn_schedule/
Traceback (most recent call last):
  File "/usr/local/lib/python3.7/site-packages/django/db/backends/utils.py", line 85, in _execute
    return self.cursor.execute(sql, params)
  File "/usr/local/lib/python3.7/site-packages/django/db/backends/mysql/base.py", line 71, in execute
    return self.cursor.execute(query, args)
  File "/usr/local/lib/python3.7/site-packages/pymysql/cursors.py", line 165, in execute
    result = self._query(query)
  File "/usr/local/lib/python3.7/site-packages/pymysql/cursors.py", line 321, in _query
    conn.query(q)
  File "/usr/local/lib/python3.7/site-packages/pymysql/connections.py", line 860, in query
    self._affected_rows = self._read_query_result(unbuffered=unbuffered)
  File "/usr/local/lib/python3.7/site-packages/pymysql/connections.py", line 1061, in _read_query_result
    result.read()
  File "/usr/local/lib/python3.7/site-packages/pymysql/connections.py", line 1349, in read
    first_packet = self.connection._read_packet()
  File "/usr/local/lib/python3.7/site-packages/pymysql/connections.py", line 1018, in _read_packet
    packet.check_error()
  File "/usr/local/lib/python3.7/site-packages/pymysql/connections.py", line 384, in check_error
    err.raise_mysql_exception(self._data)
  File "/usr/local/lib/python3.7/site-packages/pymysql/err.py", line 107, in raise_mysql_exception
    raise errorclass(errno, errval)
pymysql.err.InternalError: (1054, "Unknown column 'app_autorace_trn_schedule.Track_code1_1' in 'field list'")

The above exception was the direct cause of the following exception:

Traceback (most recent call last):
  File "/usr/local/lib/python3.7/site-packages/django/core/handlers/exception.py", line 34, in inner
    response = get_response(request)
  File "/usr/local/lib/python3.7/site-packages/django/core/handlers/base.py", line 126, in _get_response
    response = self.process_exception_by_middleware(e, request)
  File "/usr/local/lib/python3.7/site-packages/django/core/handlers/base.py", line 124, in _get_response
    response = wrapped_callback(request, *callback_args, **callback_kwargs)
  File "/usr/local/lib/python3.7/site-packages/django/contrib/admin/options.py", line 604, in wrapper
    return self.admin_site.admin_view(view)(*args, **kwargs)
  File "/usr/local/lib/python3.7/site-packages/django/utils/decorators.py", line 142, in _wrapped_view
    response = view_func(request, *args, **kwargs)
  File "/usr/local/lib/python3.7/site-packages/django/views/decorators/cache.py", line 44, in _wrapped_view_func
    response = view_func(request, *args, **kwargs)
  File "/usr/local/lib/python3.7/site-packages/django/contrib/admin/sites.py", line 223, in inner
    return view(request, *args, **kwargs)
  File "/usr/local/lib/python3.7/site-packages/django/utils/decorators.py", line 45, in _wrapper
    return bound_method(*args, **kwargs)
  File "/usr/local/lib/python3.7/site-packages/django/utils/decorators.py", line 142, in _wrapped_view
    response = view_func(request, *args, **kwargs)
  File "/usr/local/lib/python3.7/site-packages/django/contrib/admin/options.py", line 1793, in changelist_view
    'selection_note': _('0 of %(cnt)s selected') % {'cnt': len(cl.result_list)},
  File "/usr/local/lib/python3.7/site-packages/django/db/models/query.py", line 250, in __len__
    self._fetch_all()
  File "/usr/local/lib/python3.7/site-packages/django/db/models/query.py", line 1186, in _fetch_all
    self._result_cache = list(self._iterable_class(self))
  File "/usr/local/lib/python3.7/site-packages/django/db/models/query.py", line 54, in __iter__
    results = compiler.execute_sql(chunked_fetch=self.chunked_fetch, chunk_size=self.chunk_size)
  File "/usr/local/lib/python3.7/site-packages/django/db/models/sql/compiler.py", line 1065, in execute_sql
    cursor.execute(sql, params)
  File "/usr/local/lib/python3.7/site-packages/django/db/backends/utils.py", line 100, in execute
    return super().execute(sql, params)
  File "/usr/local/lib/python3.7/site-packages/django/db/backends/utils.py", line 68, in execute
    return self._execute_with_wrappers(sql, params, many=False, executor=self._execute)
  File "/usr/local/lib/python3.7/site-packages/django/db/backends/utils.py", line 77, in _execute_with_wrappers
    return executor(sql, params, many, context)
  File "/usr/local/lib/python3.7/site-packages/django/db/backends/utils.py", line 85, in _execute
    return self.cursor.execute(sql, params)
  File "/usr/local/lib/python3.7/site-packages/django/db/utils.py", line 89, in __exit__
    raise dj_exc_value.with_traceback(traceback) from exc_value
  File "/usr/local/lib/python3.7/site-packages/django/db/backends/utils.py", line 85, in _execute
    return self.cursor.execute(sql, params)
  File "/usr/local/lib/python3.7/site-packages/django/db/backends/mysql/base.py", line 71, in execute
    return self.cursor.execute(query, args)
  File "/usr/local/lib/python3.7/site-packages/pymysql/cursors.py", line 165, in execute
    result = self._query(query)
  File "/usr/local/lib/python3.7/site-packages/pymysql/cursors.py", line 321, in _query
    conn.query(q)
  File "/usr/local/lib/python3.7/site-packages/pymysql/connections.py", line 860, in query
    self._affected_rows = self._read_query_result(unbuffered=unbuffered)
  File "/usr/local/lib/python3.7/site-packages/pymysql/connections.py", line 1061, in _read_query_result
    result.read()
  File "/usr/local/lib/python3.7/site-packages/pymysql/connections.py", line 1349, in read
    first_packet = self.connection._read_packet()
  File "/usr/local/lib/python3.7/site-packages/pymysql/connections.py", line 1018, in _read_packet
    packet.check_error()
  File "/usr/local/lib/python3.7/site-packages/pymysql/connections.py", line 384, in check_error
    err.raise_mysql_exception(self._data)
  File "/usr/local/lib/python3.7/site-packages/pymysql/err.py", line 107, in raise_mysql_exception
    raise errorclass(errno, errval)
django.db.utils.InternalError: (1054, "Unknown column 'app_autorace_trn_schedule.Track_code1_1' in 'field list'")
[WARNING]	2020-04-21 10:17:44,343	module:log	django.request.log_response:228	Not Found: /favicon.ico
[WARNING]	2020-04-21 10:17:49,502	module:log	django.request.log_response:228	Not Found: /favicon.ico
[ERROR]	2020-04-21 10:17:53,200	module:log	django.request.log_response:228	Internal Server Error: /admin/app_ckeiba/trn_trifecta_dividend_tb4/
Traceback (most recent call last):
  File "/usr/local/lib/python3.7/site-packages/django/db/backends/utils.py", line 85, in _execute
    return self.cursor.execute(sql, params)
  File "/usr/local/lib/python3.7/site-packages/django/db/backends/mysql/base.py", line 71, in execute
    return self.cursor.execute(query, args)
  File "/usr/local/lib/python3.7/site-packages/pymysql/cursors.py", line 165, in execute
    result = self._query(query)
  File "/usr/local/lib/python3.7/site-packages/pymysql/cursors.py", line 321, in _query
    conn.query(q)
  File "/usr/local/lib/python3.7/site-packages/pymysql/connections.py", line 860, in query
    self._affected_rows = self._read_query_result(unbuffered=unbuffered)
  File "/usr/local/lib/python3.7/site-packages/pymysql/connections.py", line 1061, in _read_query_result
    result.read()
  File "/usr/local/lib/python3.7/site-packages/pymysql/connections.py", line 1349, in read
    first_packet = self.connection._read_packet()
  File "/usr/local/lib/python3.7/site-packages/pymysql/connections.py", line 1018, in _read_packet
    packet.check_error()
  File "/usr/local/lib/python3.7/site-packages/pymysql/connections.py", line 384, in check_error
    err.raise_mysql_exception(self._data)
  File "/usr/local/lib/python3.7/site-packages/pymysql/err.py", line 107, in raise_mysql_exception
    raise errorclass(errno, errval)
pymysql.err.ProgrammingError: (1146, "Table 'prj_sports.app_ckeiba_trn_trifecta_dividend_tb4' doesn't exist")

The above exception was the direct cause of the following exception:

Traceback (most recent call last):
  File "/usr/local/lib/python3.7/site-packages/django/core/handlers/exception.py", line 34, in inner
    response = get_response(request)
  File "/usr/local/lib/python3.7/site-packages/django/core/handlers/base.py", line 126, in _get_response
    response = self.process_exception_by_middleware(e, request)
  File "/usr/local/lib/python3.7/site-packages/django/core/handlers/base.py", line 124, in _get_response
    response = wrapped_callback(request, *callback_args, **callback_kwargs)
  File "/usr/local/lib/python3.7/site-packages/django/contrib/admin/options.py", line 604, in wrapper
    return self.admin_site.admin_view(view)(*args, **kwargs)
  File "/usr/local/lib/python3.7/site-packages/django/utils/decorators.py", line 142, in _wrapped_view
    response = view_func(request, *args, **kwargs)
  File "/usr/local/lib/python3.7/site-packages/django/views/decorators/cache.py", line 44, in _wrapped_view_func
    response = view_func(request, *args, **kwargs)
  File "/usr/local/lib/python3.7/site-packages/django/contrib/admin/sites.py", line 223, in inner
    return view(request, *args, **kwargs)
  File "/usr/local/lib/python3.7/site-packages/django/utils/decorators.py", line 45, in _wrapper
    return bound_method(*args, **kwargs)
  File "/usr/local/lib/python3.7/site-packages/django/utils/decorators.py", line 142, in _wrapped_view
    response = view_func(request, *args, **kwargs)
  File "/usr/local/lib/python3.7/site-packages/django/contrib/admin/options.py", line 1675, in changelist_view
    cl = self.get_changelist_instance(request)
  File "/usr/local/lib/python3.7/site-packages/django/contrib/admin/options.py", line 742, in get_changelist_instance
    sortable_by,
  File "/usr/local/lib/python3.7/site-packages/django/contrib/admin/views/main.py", line 81, in __init__
    self.get_results(request)
  File "/usr/local/lib/python3.7/site-packages/django/contrib/admin/views/main.py", line 209, in get_results
    result_count = paginator.count
  File "/usr/local/lib/python3.7/site-packages/django/utils/functional.py", line 37, in __get__
    res = instance.__dict__[self.name] = self.func(instance)
  File "/usr/local/lib/python3.7/site-packages/django/core/paginator.py", line 87, in count
    return self.object_list.count()
  File "/usr/local/lib/python3.7/site-packages/django/db/models/query.py", line 383, in count
    return self.query.get_count(using=self.db)
  File "/usr/local/lib/python3.7/site-packages/django/db/models/sql/query.py", line 498, in get_count
    number = obj.get_aggregation(using, ['__count'])['__count']
  File "/usr/local/lib/python3.7/site-packages/django/db/models/sql/query.py", line 483, in get_aggregation
    result = compiler.execute_sql(SINGLE)
  File "/usr/local/lib/python3.7/site-packages/django/db/models/sql/compiler.py", line 1065, in execute_sql
    cursor.execute(sql, params)
  File "/usr/local/lib/python3.7/site-packages/django/db/backends/utils.py", line 100, in execute
    return super().execute(sql, params)
  File "/usr/local/lib/python3.7/site-packages/django/db/backends/utils.py", line 68, in execute
    return self._execute_with_wrappers(sql, params, many=False, executor=self._execute)
  File "/usr/local/lib/python3.7/site-packages/django/db/backends/utils.py", line 77, in _execute_with_wrappers
    return executor(sql, params, many, context)
  File "/usr/local/lib/python3.7/site-packages/django/db/backends/utils.py", line 85, in _execute
    return self.cursor.execute(sql, params)
  File "/usr/local/lib/python3.7/site-packages/django/db/utils.py", line 89, in __exit__
    raise dj_exc_value.with_traceback(traceback) from exc_value
  File "/usr/local/lib/python3.7/site-packages/django/db/backends/utils.py", line 85, in _execute
    return self.cursor.execute(sql, params)
  File "/usr/local/lib/python3.7/site-packages/django/db/backends/mysql/base.py", line 71, in execute
    return self.cursor.execute(query, args)
  File "/usr/local/lib/python3.7/site-packages/pymysql/cursors.py", line 165, in execute
    result = self._query(query)
  File "/usr/local/lib/python3.7/site-packages/pymysql/cursors.py", line 321, in _query
    conn.query(q)
  File "/usr/local/lib/python3.7/site-packages/pymysql/connections.py", line 860, in query
    self._affected_rows = self._read_query_result(unbuffered=unbuffered)
  File "/usr/local/lib/python3.7/site-packages/pymysql/connections.py", line 1061, in _read_query_result
    result.read()
  File "/usr/local/lib/python3.7/site-packages/pymysql/connections.py", line 1349, in read
    first_packet = self.connection._read_packet()
  File "/usr/local/lib/python3.7/site-packages/pymysql/connections.py", line 1018, in _read_packet
    packet.check_error()
  File "/usr/local/lib/python3.7/site-packages/pymysql/connections.py", line 384, in check_error
    err.raise_mysql_exception(self._data)
  File "/usr/local/lib/python3.7/site-packages/pymysql/err.py", line 107, in raise_mysql_exception
    raise errorclass(errno, errval)
django.db.utils.ProgrammingError: (1146, "Table 'prj_sports.app_ckeiba_trn_trifecta_dividend_tb4' doesn't exist")
[WARNING]	2020-04-21 10:17:53,248	module:log	django.request.log_response:228	Not Found: /favicon.ico
[ERROR]	2020-04-21 10:17:56,961	module:log	django.request.log_response:228	Internal Server Error: /admin/app_ckeiba/trn_running_list_b_sub/
Traceback (most recent call last):
  File "/usr/local/lib/python3.7/site-packages/django/db/backends/utils.py", line 85, in _execute
    return self.cursor.execute(sql, params)
  File "/usr/local/lib/python3.7/site-packages/django/db/backends/mysql/base.py", line 71, in execute
    return self.cursor.execute(query, args)
  File "/usr/local/lib/python3.7/site-packages/pymysql/cursors.py", line 165, in execute
    result = self._query(query)
  File "/usr/local/lib/python3.7/site-packages/pymysql/cursors.py", line 321, in _query
    conn.query(q)
  File "/usr/local/lib/python3.7/site-packages/pymysql/connections.py", line 860, in query
    self._affected_rows = self._read_query_result(unbuffered=unbuffered)
  File "/usr/local/lib/python3.7/site-packages/pymysql/connections.py", line 1061, in _read_query_result
    result.read()
  File "/usr/local/lib/python3.7/site-packages/pymysql/connections.py", line 1349, in read
    first_packet = self.connection._read_packet()
  File "/usr/local/lib/python3.7/site-packages/pymysql/connections.py", line 1018, in _read_packet
    packet.check_error()
  File "/usr/local/lib/python3.7/site-packages/pymysql/connections.py", line 384, in check_error
    err.raise_mysql_exception(self._data)
  File "/usr/local/lib/python3.7/site-packages/pymysql/err.py", line 107, in raise_mysql_exception
    raise errorclass(errno, errval)
pymysql.err.ProgrammingError: (1146, "Table 'prj_sports.app_ckeiba_trn_running_list_b_sub' doesn't exist")

The above exception was the direct cause of the following exception:

Traceback (most recent call last):
  File "/usr/local/lib/python3.7/site-packages/django/core/handlers/exception.py", line 34, in inner
    response = get_response(request)
  File "/usr/local/lib/python3.7/site-packages/django/core/handlers/base.py", line 126, in _get_response
    response = self.process_exception_by_middleware(e, request)
  File "/usr/local/lib/python3.7/site-packages/django/core/handlers/base.py", line 124, in _get_response
    response = wrapped_callback(request, *callback_args, **callback_kwargs)
  File "/usr/local/lib/python3.7/site-packages/django/contrib/admin/options.py", line 604, in wrapper
    return self.admin_site.admin_view(view)(*args, **kwargs)
  File "/usr/local/lib/python3.7/site-packages/django/utils/decorators.py", line 142, in _wrapped_view
    response = view_func(request, *args, **kwargs)
  File "/usr/local/lib/python3.7/site-packages/django/views/decorators/cache.py", line 44, in _wrapped_view_func
    response = view_func(request, *args, **kwargs)
  File "/usr/local/lib/python3.7/site-packages/django/contrib/admin/sites.py", line 223, in inner
    return view(request, *args, **kwargs)
  File "/usr/local/lib/python3.7/site-packages/django/utils/decorators.py", line 45, in _wrapper
    return bound_method(*args, **kwargs)
  File "/usr/local/lib/python3.7/site-packages/django/utils/decorators.py", line 142, in _wrapped_view
    response = view_func(request, *args, **kwargs)
  File "/usr/local/lib/python3.7/site-packages/django/contrib/admin/options.py", line 1675, in changelist_view
    cl = self.get_changelist_instance(request)
  File "/usr/local/lib/python3.7/site-packages/django/contrib/admin/options.py", line 742, in get_changelist_instance
    sortable_by,
  File "/usr/local/lib/python3.7/site-packages/django/contrib/admin/views/main.py", line 81, in __init__
    self.get_results(request)
  File "/usr/local/lib/python3.7/site-packages/django/contrib/admin/views/main.py", line 209, in get_results
    result_count = paginator.count
  File "/usr/local/lib/python3.7/site-packages/django/utils/functional.py", line 37, in __get__
    res = instance.__dict__[self.name] = self.func(instance)
  File "/usr/local/lib/python3.7/site-packages/django/core/paginator.py", line 87, in count
    return self.object_list.count()
  File "/usr/local/lib/python3.7/site-packages/django/db/models/query.py", line 383, in count
    return self.query.get_count(using=self.db)
  File "/usr/local/lib/python3.7/site-packages/django/db/models/sql/query.py", line 498, in get_count
    number = obj.get_aggregation(using, ['__count'])['__count']
  File "/usr/local/lib/python3.7/site-packages/django/db/models/sql/query.py", line 483, in get_aggregation
    result = compiler.execute_sql(SINGLE)
  File "/usr/local/lib/python3.7/site-packages/django/db/models/sql/compiler.py", line 1065, in execute_sql
    cursor.execute(sql, params)
  File "/usr/local/lib/python3.7/site-packages/django/db/backends/utils.py", line 100, in execute
    return super().execute(sql, params)
  File "/usr/local/lib/python3.7/site-packages/django/db/backends/utils.py", line 68, in execute
    return self._execute_with_wrappers(sql, params, many=False, executor=self._execute)
  File "/usr/local/lib/python3.7/site-packages/django/db/backends/utils.py", line 77, in _execute_with_wrappers
    return executor(sql, params, many, context)
  File "/usr/local/lib/python3.7/site-packages/django/db/backends/utils.py", line 85, in _execute
    return self.cursor.execute(sql, params)
  File "/usr/local/lib/python3.7/site-packages/django/db/utils.py", line 89, in __exit__
    raise dj_exc_value.with_traceback(traceback) from exc_value
  File "/usr/local/lib/python3.7/site-packages/django/db/backends/utils.py", line 85, in _execute
    return self.cursor.execute(sql, params)
  File "/usr/local/lib/python3.7/site-packages/django/db/backends/mysql/base.py", line 71, in execute
    return self.cursor.execute(query, args)
  File "/usr/local/lib/python3.7/site-packages/pymysql/cursors.py", line 165, in execute
    result = self._query(query)
  File "/usr/local/lib/python3.7/site-packages/pymysql/cursors.py", line 321, in _query
    conn.query(q)
  File "/usr/local/lib/python3.7/site-packages/pymysql/connections.py", line 860, in query
    self._affected_rows = self._read_query_result(unbuffered=unbuffered)
  File "/usr/local/lib/python3.7/site-packages/pymysql/connections.py", line 1061, in _read_query_result
    result.read()
  File "/usr/local/lib/python3.7/site-packages/pymysql/connections.py", line 1349, in read
    first_packet = self.connection._read_packet()
  File "/usr/local/lib/python3.7/site-packages/pymysql/connections.py", line 1018, in _read_packet
    packet.check_error()
  File "/usr/local/lib/python3.7/site-packages/pymysql/connections.py", line 384, in check_error
    err.raise_mysql_exception(self._data)
  File "/usr/local/lib/python3.7/site-packages/pymysql/err.py", line 107, in raise_mysql_exception
    raise errorclass(errno, errval)
django.db.utils.ProgrammingError: (1146, "Table 'prj_sports.app_ckeiba_trn_running_list_b_sub' doesn't exist")
[WARNING]	2020-04-21 10:17:57,008	module:log	django.request.log_response:228	Not Found: /favicon.ico
[WARNING]	2020-04-21 10:18:08,638	module:log	django.request.log_response:228	Not Found: /favicon.ico
[WARNING]	2020-04-21 10:18:11,692	module:log	django.request.log_response:228	Not Found: /favicon.ico
[WARNING]	2020-04-21 10:18:14,689	module:log	django.request.log_response:228	Not Found: /favicon.ico
[WARNING]	2020-04-21 10:18:17,155	module:log	django.request.log_response:228	Not Found: /favicon.ico
[WARNING]	2020-04-21 10:18:23,592	module:log	django.request.log_response:228	Not Found: /favicon.ico
[ERROR]	2020-04-21 10:18:34,414	module:log	django.request.log_response:228	Internal Server Error: /admin/app_sumo/tran_banzuke/
Traceback (most recent call last):
  File "/usr/local/lib/python3.7/site-packages/django/db/backends/utils.py", line 85, in _execute
    return self.cursor.execute(sql, params)
  File "/usr/local/lib/python3.7/site-packages/django/db/backends/mysql/base.py", line 71, in execute
    return self.cursor.execute(query, args)
  File "/usr/local/lib/python3.7/site-packages/pymysql/cursors.py", line 165, in execute
    result = self._query(query)
  File "/usr/local/lib/python3.7/site-packages/pymysql/cursors.py", line 321, in _query
    conn.query(q)
  File "/usr/local/lib/python3.7/site-packages/pymysql/connections.py", line 860, in query
    self._affected_rows = self._read_query_result(unbuffered=unbuffered)
  File "/usr/local/lib/python3.7/site-packages/pymysql/connections.py", line 1061, in _read_query_result
    result.read()
  File "/usr/local/lib/python3.7/site-packages/pymysql/connections.py", line 1349, in read
    first_packet = self.connection._read_packet()
  File "/usr/local/lib/python3.7/site-packages/pymysql/connections.py", line 1018, in _read_packet
    packet.check_error()
  File "/usr/local/lib/python3.7/site-packages/pymysql/connections.py", line 384, in check_error
    err.raise_mysql_exception(self._data)
  File "/usr/local/lib/python3.7/site-packages/pymysql/err.py", line 107, in raise_mysql_exception
    raise errorclass(errno, errval)
pymysql.err.InternalError: (1054, "Unknown column 'app_sumo_tran_banzuke.Sys_status_id' in 'field list'")

The above exception was the direct cause of the following exception:

Traceback (most recent call last):
  File "/usr/local/lib/python3.7/site-packages/django/core/handlers/exception.py", line 34, in inner
    response = get_response(request)
  File "/usr/local/lib/python3.7/site-packages/django/core/handlers/base.py", line 126, in _get_response
    response = self.process_exception_by_middleware(e, request)
  File "/usr/local/lib/python3.7/site-packages/django/core/handlers/base.py", line 124, in _get_response
    response = wrapped_callback(request, *callback_args, **callback_kwargs)
  File "/usr/local/lib/python3.7/site-packages/django/contrib/admin/options.py", line 604, in wrapper
    return self.admin_site.admin_view(view)(*args, **kwargs)
  File "/usr/local/lib/python3.7/site-packages/django/utils/decorators.py", line 142, in _wrapped_view
    response = view_func(request, *args, **kwargs)
  File "/usr/local/lib/python3.7/site-packages/django/views/decorators/cache.py", line 44, in _wrapped_view_func
    response = view_func(request, *args, **kwargs)
  File "/usr/local/lib/python3.7/site-packages/django/contrib/admin/sites.py", line 223, in inner
    return view(request, *args, **kwargs)
  File "/usr/local/lib/python3.7/site-packages/django/utils/decorators.py", line 45, in _wrapper
    return bound_method(*args, **kwargs)
  File "/usr/local/lib/python3.7/site-packages/django/utils/decorators.py", line 142, in _wrapped_view
    response = view_func(request, *args, **kwargs)
  File "/usr/local/lib/python3.7/site-packages/django/contrib/admin/options.py", line 1793, in changelist_view
    'selection_note': _('0 of %(cnt)s selected') % {'cnt': len(cl.result_list)},
  File "/usr/local/lib/python3.7/site-packages/django/db/models/query.py", line 250, in __len__
    self._fetch_all()
  File "/usr/local/lib/python3.7/site-packages/django/db/models/query.py", line 1186, in _fetch_all
    self._result_cache = list(self._iterable_class(self))
  File "/usr/local/lib/python3.7/site-packages/django/db/models/query.py", line 54, in __iter__
    results = compiler.execute_sql(chunked_fetch=self.chunked_fetch, chunk_size=self.chunk_size)
  File "/usr/local/lib/python3.7/site-packages/django/db/models/sql/compiler.py", line 1065, in execute_sql
    cursor.execute(sql, params)
  File "/usr/local/lib/python3.7/site-packages/django/db/backends/utils.py", line 100, in execute
    return super().execute(sql, params)
  File "/usr/local/lib/python3.7/site-packages/django/db/backends/utils.py", line 68, in execute
    return self._execute_with_wrappers(sql, params, many=False, executor=self._execute)
  File "/usr/local/lib/python3.7/site-packages/django/db/backends/utils.py", line 77, in _execute_with_wrappers
    return executor(sql, params, many, context)
  File "/usr/local/lib/python3.7/site-packages/django/db/backends/utils.py", line 85, in _execute
    return self.cursor.execute(sql, params)
  File "/usr/local/lib/python3.7/site-packages/django/db/utils.py", line 89, in __exit__
    raise dj_exc_value.with_traceback(traceback) from exc_value
  File "/usr/local/lib/python3.7/site-packages/django/db/backends/utils.py", line 85, in _execute
    return self.cursor.execute(sql, params)
  File "/usr/local/lib/python3.7/site-packages/django/db/backends/mysql/base.py", line 71, in execute
    return self.cursor.execute(query, args)
  File "/usr/local/lib/python3.7/site-packages/pymysql/cursors.py", line 165, in execute
    result = self._query(query)
  File "/usr/local/lib/python3.7/site-packages/pymysql/cursors.py", line 321, in _query
    conn.query(q)
  File "/usr/local/lib/python3.7/site-packages/pymysql/connections.py", line 860, in query
    self._affected_rows = self._read_query_result(unbuffered=unbuffered)
  File "/usr/local/lib/python3.7/site-packages/pymysql/connections.py", line 1061, in _read_query_result
    result.read()
  File "/usr/local/lib/python3.7/site-packages/pymysql/connections.py", line 1349, in read
    first_packet = self.connection._read_packet()
  File "/usr/local/lib/python3.7/site-packages/pymysql/connections.py", line 1018, in _read_packet
    packet.check_error()
  File "/usr/local/lib/python3.7/site-packages/pymysql/connections.py", line 384, in check_error
    err.raise_mysql_exception(self._data)
  File "/usr/local/lib/python3.7/site-packages/pymysql/err.py", line 107, in raise_mysql_exception
    raise errorclass(errno, errval)
django.db.utils.InternalError: (1054, "Unknown column 'app_sumo_tran_banzuke.Sys_status_id' in 'field list'")
[WARNING]	2020-04-21 10:18:34,462	module:log	django.request.log_response:228	Not Found: /favicon.ico
[ERROR]	2020-04-21 10:18:36,435	module:log	django.request.log_response:228	Internal Server Error: /admin/app_sumo/tran_banzuke_forecast/
Traceback (most recent call last):
  File "/usr/local/lib/python3.7/site-packages/django/db/backends/utils.py", line 85, in _execute
    return self.cursor.execute(sql, params)
  File "/usr/local/lib/python3.7/site-packages/django/db/backends/mysql/base.py", line 71, in execute
    return self.cursor.execute(query, args)
  File "/usr/local/lib/python3.7/site-packages/pymysql/cursors.py", line 165, in execute
    result = self._query(query)
  File "/usr/local/lib/python3.7/site-packages/pymysql/cursors.py", line 321, in _query
    conn.query(q)
  File "/usr/local/lib/python3.7/site-packages/pymysql/connections.py", line 860, in query
    self._affected_rows = self._read_query_result(unbuffered=unbuffered)
  File "/usr/local/lib/python3.7/site-packages/pymysql/connections.py", line 1061, in _read_query_result
    result.read()
  File "/usr/local/lib/python3.7/site-packages/pymysql/connections.py", line 1349, in read
    first_packet = self.connection._read_packet()
  File "/usr/local/lib/python3.7/site-packages/pymysql/connections.py", line 1018, in _read_packet
    packet.check_error()
  File "/usr/local/lib/python3.7/site-packages/pymysql/connections.py", line 384, in check_error
    err.raise_mysql_exception(self._data)
  File "/usr/local/lib/python3.7/site-packages/pymysql/err.py", line 107, in raise_mysql_exception
    raise errorclass(errno, errval)
pymysql.err.ProgrammingError: (1146, "Table 'prj_sports.app_sumo_tran_banzuke_forecast' doesn't exist")

The above exception was the direct cause of the following exception:

Traceback (most recent call last):
  File "/usr/local/lib/python3.7/site-packages/django/core/handlers/exception.py", line 34, in inner
    response = get_response(request)
  File "/usr/local/lib/python3.7/site-packages/django/core/handlers/base.py", line 126, in _get_response
    response = self.process_exception_by_middleware(e, request)
  File "/usr/local/lib/python3.7/site-packages/django/core/handlers/base.py", line 124, in _get_response
    response = wrapped_callback(request, *callback_args, **callback_kwargs)
  File "/usr/local/lib/python3.7/site-packages/django/contrib/admin/options.py", line 604, in wrapper
    return self.admin_site.admin_view(view)(*args, **kwargs)
  File "/usr/local/lib/python3.7/site-packages/django/utils/decorators.py", line 142, in _wrapped_view
    response = view_func(request, *args, **kwargs)
  File "/usr/local/lib/python3.7/site-packages/django/views/decorators/cache.py", line 44, in _wrapped_view_func
    response = view_func(request, *args, **kwargs)
  File "/usr/local/lib/python3.7/site-packages/django/contrib/admin/sites.py", line 223, in inner
    return view(request, *args, **kwargs)
  File "/usr/local/lib/python3.7/site-packages/django/utils/decorators.py", line 45, in _wrapper
    return bound_method(*args, **kwargs)
  File "/usr/local/lib/python3.7/site-packages/django/utils/decorators.py", line 142, in _wrapped_view
    response = view_func(request, *args, **kwargs)
  File "/usr/local/lib/python3.7/site-packages/django/contrib/admin/options.py", line 1675, in changelist_view
    cl = self.get_changelist_instance(request)
  File "/usr/local/lib/python3.7/site-packages/django/contrib/admin/options.py", line 742, in get_changelist_instance
    sortable_by,
  File "/usr/local/lib/python3.7/site-packages/django/contrib/admin/views/main.py", line 81, in __init__
    self.get_results(request)
  File "/usr/local/lib/python3.7/site-packages/django/contrib/admin/views/main.py", line 209, in get_results
    result_count = paginator.count
  File "/usr/local/lib/python3.7/site-packages/django/utils/functional.py", line 37, in __get__
    res = instance.__dict__[self.name] = self.func(instance)
  File "/usr/local/lib/python3.7/site-packages/django/core/paginator.py", line 87, in count
    return self.object_list.count()
  File "/usr/local/lib/python3.7/site-packages/django/db/models/query.py", line 383, in count
    return self.query.get_count(using=self.db)
  File "/usr/local/lib/python3.7/site-packages/django/db/models/sql/query.py", line 498, in get_count
    number = obj.get_aggregation(using, ['__count'])['__count']
  File "/usr/local/lib/python3.7/site-packages/django/db/models/sql/query.py", line 483, in get_aggregation
    result = compiler.execute_sql(SINGLE)
  File "/usr/local/lib/python3.7/site-packages/django/db/models/sql/compiler.py", line 1065, in execute_sql
    cursor.execute(sql, params)
  File "/usr/local/lib/python3.7/site-packages/django/db/backends/utils.py", line 100, in execute
    return super().execute(sql, params)
  File "/usr/local/lib/python3.7/site-packages/django/db/backends/utils.py", line 68, in execute
    return self._execute_with_wrappers(sql, params, many=False, executor=self._execute)
  File "/usr/local/lib/python3.7/site-packages/django/db/backends/utils.py", line 77, in _execute_with_wrappers
    return executor(sql, params, many, context)
  File "/usr/local/lib/python3.7/site-packages/django/db/backends/utils.py", line 85, in _execute
    return self.cursor.execute(sql, params)
  File "/usr/local/lib/python3.7/site-packages/django/db/utils.py", line 89, in __exit__
    raise dj_exc_value.with_traceback(traceback) from exc_value
  File "/usr/local/lib/python3.7/site-packages/django/db/backends/utils.py", line 85, in _execute
    return self.cursor.execute(sql, params)
  File "/usr/local/lib/python3.7/site-packages/django/db/backends/mysql/base.py", line 71, in execute
    return self.cursor.execute(query, args)
  File "/usr/local/lib/python3.7/site-packages/pymysql/cursors.py", line 165, in execute
    result = self._query(query)
  File "/usr/local/lib/python3.7/site-packages/pymysql/cursors.py", line 321, in _query
    conn.query(q)
  File "/usr/local/lib/python3.7/site-packages/pymysql/connections.py", line 860, in query
    self._affected_rows = self._read_query_result(unbuffered=unbuffered)
  File "/usr/local/lib/python3.7/site-packages/pymysql/connections.py", line 1061, in _read_query_result
    result.read()
  File "/usr/local/lib/python3.7/site-packages/pymysql/connections.py", line 1349, in read
    first_packet = self.connection._read_packet()
  File "/usr/local/lib/python3.7/site-packages/pymysql/connections.py", line 1018, in _read_packet
    packet.check_error()
  File "/usr/local/lib/python3.7/site-packages/pymysql/connections.py", line 384, in check_error
    err.raise_mysql_exception(self._data)
  File "/usr/local/lib/python3.7/site-packages/pymysql/err.py", line 107, in raise_mysql_exception
    raise errorclass(errno, errval)
django.db.utils.ProgrammingError: (1146, "Table 'prj_sports.app_sumo_tran_banzuke_forecast' doesn't exist")
[WARNING]	2020-04-21 10:18:36,483	module:log	django.request.log_response:228	Not Found: /favicon.ico
[ERROR]	2020-04-21 10:18:39,923	module:log	django.request.log_response:228	Internal Server Error: /admin/app_sumo/tran_banzuke/
Traceback (most recent call last):
  File "/usr/local/lib/python3.7/site-packages/django/db/backends/utils.py", line 85, in _execute
    return self.cursor.execute(sql, params)
  File "/usr/local/lib/python3.7/site-packages/django/db/backends/mysql/base.py", line 71, in execute
    return self.cursor.execute(query, args)
  File "/usr/local/lib/python3.7/site-packages/pymysql/cursors.py", line 165, in execute
    result = self._query(query)
  File "/usr/local/lib/python3.7/site-packages/pymysql/cursors.py", line 321, in _query
    conn.query(q)
  File "/usr/local/lib/python3.7/site-packages/pymysql/connections.py", line 860, in query
    self._affected_rows = self._read_query_result(unbuffered=unbuffered)
  File "/usr/local/lib/python3.7/site-packages/pymysql/connections.py", line 1061, in _read_query_result
    result.read()
  File "/usr/local/lib/python3.7/site-packages/pymysql/connections.py", line 1349, in read
    first_packet = self.connection._read_packet()
  File "/usr/local/lib/python3.7/site-packages/pymysql/connections.py", line 1018, in _read_packet
    packet.check_error()
  File "/usr/local/lib/python3.7/site-packages/pymysql/connections.py", line 384, in check_error
    err.raise_mysql_exception(self._data)
  File "/usr/local/lib/python3.7/site-packages/pymysql/err.py", line 107, in raise_mysql_exception
    raise errorclass(errno, errval)
pymysql.err.InternalError: (1054, "Unknown column 'app_sumo_tran_banzuke.Sys_status_id' in 'field list'")

The above exception was the direct cause of the following exception:

Traceback (most recent call last):
  File "/usr/local/lib/python3.7/site-packages/django/core/handlers/exception.py", line 34, in inner
    response = get_response(request)
  File "/usr/local/lib/python3.7/site-packages/django/core/handlers/base.py", line 126, in _get_response
    response = self.process_exception_by_middleware(e, request)
  File "/usr/local/lib/python3.7/site-packages/django/core/handlers/base.py", line 124, in _get_response
    response = wrapped_callback(request, *callback_args, **callback_kwargs)
  File "/usr/local/lib/python3.7/site-packages/django/contrib/admin/options.py", line 604, in wrapper
    return self.admin_site.admin_view(view)(*args, **kwargs)
  File "/usr/local/lib/python3.7/site-packages/django/utils/decorators.py", line 142, in _wrapped_view
    response = view_func(request, *args, **kwargs)
  File "/usr/local/lib/python3.7/site-packages/django/views/decorators/cache.py", line 44, in _wrapped_view_func
    response = view_func(request, *args, **kwargs)
  File "/usr/local/lib/python3.7/site-packages/django/contrib/admin/sites.py", line 223, in inner
    return view(request, *args, **kwargs)
  File "/usr/local/lib/python3.7/site-packages/django/utils/decorators.py", line 45, in _wrapper
    return bound_method(*args, **kwargs)
  File "/usr/local/lib/python3.7/site-packages/django/utils/decorators.py", line 142, in _wrapped_view
    response = view_func(request, *args, **kwargs)
  File "/usr/local/lib/python3.7/site-packages/django/contrib/admin/options.py", line 1793, in changelist_view
    'selection_note': _('0 of %(cnt)s selected') % {'cnt': len(cl.result_list)},
  File "/usr/local/lib/python3.7/site-packages/django/db/models/query.py", line 250, in __len__
    self._fetch_all()
  File "/usr/local/lib/python3.7/site-packages/django/db/models/query.py", line 1186, in _fetch_all
    self._result_cache = list(self._iterable_class(self))
  File "/usr/local/lib/python3.7/site-packages/django/db/models/query.py", line 54, in __iter__
    results = compiler.execute_sql(chunked_fetch=self.chunked_fetch, chunk_size=self.chunk_size)
  File "/usr/local/lib/python3.7/site-packages/django/db/models/sql/compiler.py", line 1065, in execute_sql
    cursor.execute(sql, params)
  File "/usr/local/lib/python3.7/site-packages/django/db/backends/utils.py", line 100, in execute
    return super().execute(sql, params)
  File "/usr/local/lib/python3.7/site-packages/django/db/backends/utils.py", line 68, in execute
    return self._execute_with_wrappers(sql, params, many=False, executor=self._execute)
  File "/usr/local/lib/python3.7/site-packages/django/db/backends/utils.py", line 77, in _execute_with_wrappers
    return executor(sql, params, many, context)
  File "/usr/local/lib/python3.7/site-packages/django/db/backends/utils.py", line 85, in _execute
    return self.cursor.execute(sql, params)
  File "/usr/local/lib/python3.7/site-packages/django/db/utils.py", line 89, in __exit__
    raise dj_exc_value.with_traceback(traceback) from exc_value
  File "/usr/local/lib/python3.7/site-packages/django/db/backends/utils.py", line 85, in _execute
    return self.cursor.execute(sql, params)
  File "/usr/local/lib/python3.7/site-packages/django/db/backends/mysql/base.py", line 71, in execute
    return self.cursor.execute(query, args)
  File "/usr/local/lib/python3.7/site-packages/pymysql/cursors.py", line 165, in execute
    result = self._query(query)
  File "/usr/local/lib/python3.7/site-packages/pymysql/cursors.py", line 321, in _query
    conn.query(q)
  File "/usr/local/lib/python3.7/site-packages/pymysql/connections.py", line 860, in query
    self._affected_rows = self._read_query_result(unbuffered=unbuffered)
  File "/usr/local/lib/python3.7/site-packages/pymysql/connections.py", line 1061, in _read_query_result
    result.read()
  File "/usr/local/lib/python3.7/site-packages/pymysql/connections.py", line 1349, in read
    first_packet = self.connection._read_packet()
  File "/usr/local/lib/python3.7/site-packages/pymysql/connections.py", line 1018, in _read_packet
    packet.check_error()
  File "/usr/local/lib/python3.7/site-packages/pymysql/connections.py", line 384, in check_error
    err.raise_mysql_exception(self._data)
  File "/usr/local/lib/python3.7/site-packages/pymysql/err.py", line 107, in raise_mysql_exception
    raise errorclass(errno, errval)
django.db.utils.InternalError: (1054, "Unknown column 'app_sumo_tran_banzuke.Sys_status_id' in 'field list'")
[ERROR]	2020-04-21 10:18:47,281	module:log	django.request.log_response:228	Internal Server Error: /admin/app_sumo/tran_banzuke_forecast/
Traceback (most recent call last):
  File "/usr/local/lib/python3.7/site-packages/django/db/backends/utils.py", line 85, in _execute
    return self.cursor.execute(sql, params)
  File "/usr/local/lib/python3.7/site-packages/django/db/backends/mysql/base.py", line 71, in execute
    return self.cursor.execute(query, args)
  File "/usr/local/lib/python3.7/site-packages/pymysql/cursors.py", line 165, in execute
    result = self._query(query)
  File "/usr/local/lib/python3.7/site-packages/pymysql/cursors.py", line 321, in _query
    conn.query(q)
  File "/usr/local/lib/python3.7/site-packages/pymysql/connections.py", line 860, in query
    self._affected_rows = self._read_query_result(unbuffered=unbuffered)
  File "/usr/local/lib/python3.7/site-packages/pymysql/connections.py", line 1061, in _read_query_result
    result.read()
  File "/usr/local/lib/python3.7/site-packages/pymysql/connections.py", line 1349, in read
    first_packet = self.connection._read_packet()
  File "/usr/local/lib/python3.7/site-packages/pymysql/connections.py", line 1018, in _read_packet
    packet.check_error()
  File "/usr/local/lib/python3.7/site-packages/pymysql/connections.py", line 384, in check_error
    err.raise_mysql_exception(self._data)
  File "/usr/local/lib/python3.7/site-packages/pymysql/err.py", line 107, in raise_mysql_exception
    raise errorclass(errno, errval)
pymysql.err.ProgrammingError: (1146, "Table 'prj_sports.app_sumo_tran_banzuke_forecast' doesn't exist")

The above exception was the direct cause of the following exception:

Traceback (most recent call last):
  File "/usr/local/lib/python3.7/site-packages/django/core/handlers/exception.py", line 34, in inner
    response = get_response(request)
  File "/usr/local/lib/python3.7/site-packages/django/core/handlers/base.py", line 126, in _get_response
    response = self.process_exception_by_middleware(e, request)
  File "/usr/local/lib/python3.7/site-packages/django/core/handlers/base.py", line 124, in _get_response
    response = wrapped_callback(request, *callback_args, **callback_kwargs)
  File "/usr/local/lib/python3.7/site-packages/django/contrib/admin/options.py", line 604, in wrapper
    return self.admin_site.admin_view(view)(*args, **kwargs)
  File "/usr/local/lib/python3.7/site-packages/django/utils/decorators.py", line 142, in _wrapped_view
    response = view_func(request, *args, **kwargs)
  File "/usr/local/lib/python3.7/site-packages/django/views/decorators/cache.py", line 44, in _wrapped_view_func
    response = view_func(request, *args, **kwargs)
  File "/usr/local/lib/python3.7/site-packages/django/contrib/admin/sites.py", line 223, in inner
    return view(request, *args, **kwargs)
  File "/usr/local/lib/python3.7/site-packages/django/utils/decorators.py", line 45, in _wrapper
    return bound_method(*args, **kwargs)
  File "/usr/local/lib/python3.7/site-packages/django/utils/decorators.py", line 142, in _wrapped_view
    response = view_func(request, *args, **kwargs)
  File "/usr/local/lib/python3.7/site-packages/django/contrib/admin/options.py", line 1675, in changelist_view
    cl = self.get_changelist_instance(request)
  File "/usr/local/lib/python3.7/site-packages/django/contrib/admin/options.py", line 742, in get_changelist_instance
    sortable_by,
  File "/usr/local/lib/python3.7/site-packages/django/contrib/admin/views/main.py", line 81, in __init__
    self.get_results(request)
  File "/usr/local/lib/python3.7/site-packages/django/contrib/admin/views/main.py", line 209, in get_results
    result_count = paginator.count
  File "/usr/local/lib/python3.7/site-packages/django/utils/functional.py", line 37, in __get__
    res = instance.__dict__[self.name] = self.func(instance)
  File "/usr/local/lib/python3.7/site-packages/django/core/paginator.py", line 87, in count
    return self.object_list.count()
  File "/usr/local/lib/python3.7/site-packages/django/db/models/query.py", line 383, in count
    return self.query.get_count(using=self.db)
  File "/usr/local/lib/python3.7/site-packages/django/db/models/sql/query.py", line 498, in get_count
    number = obj.get_aggregation(using, ['__count'])['__count']
  File "/usr/local/lib/python3.7/site-packages/django/db/models/sql/query.py", line 483, in get_aggregation
    result = compiler.execute_sql(SINGLE)
  File "/usr/local/lib/python3.7/site-packages/django/db/models/sql/compiler.py", line 1065, in execute_sql
    cursor.execute(sql, params)
  File "/usr/local/lib/python3.7/site-packages/django/db/backends/utils.py", line 100, in execute
    return super().execute(sql, params)
  File "/usr/local/lib/python3.7/site-packages/django/db/backends/utils.py", line 68, in execute
    return self._execute_with_wrappers(sql, params, many=False, executor=self._execute)
  File "/usr/local/lib/python3.7/site-packages/django/db/backends/utils.py", line 77, in _execute_with_wrappers
    return executor(sql, params, many, context)
  File "/usr/local/lib/python3.7/site-packages/django/db/backends/utils.py", line 85, in _execute
    return self.cursor.execute(sql, params)
  File "/usr/local/lib/python3.7/site-packages/django/db/utils.py", line 89, in __exit__
    raise dj_exc_value.with_traceback(traceback) from exc_value
  File "/usr/local/lib/python3.7/site-packages/django/db/backends/utils.py", line 85, in _execute
    return self.cursor.execute(sql, params)
  File "/usr/local/lib/python3.7/site-packages/django/db/backends/mysql/base.py", line 71, in execute
    return self.cursor.execute(query, args)
  File "/usr/local/lib/python3.7/site-packages/pymysql/cursors.py", line 165, in execute
    result = self._query(query)
  File "/usr/local/lib/python3.7/site-packages/pymysql/cursors.py", line 321, in _query
    conn.query(q)
  File "/usr/local/lib/python3.7/site-packages/pymysql/connections.py", line 860, in query
    self._affected_rows = self._read_query_result(unbuffered=unbuffered)
  File "/usr/local/lib/python3.7/site-packages/pymysql/connections.py", line 1061, in _read_query_result
    result.read()
  File "/usr/local/lib/python3.7/site-packages/pymysql/connections.py", line 1349, in read
    first_packet = self.connection._read_packet()
  File "/usr/local/lib/python3.7/site-packages/pymysql/connections.py", line 1018, in _read_packet
    packet.check_error()
  File "/usr/local/lib/python3.7/site-packages/pymysql/connections.py", line 384, in check_error
    err.raise_mysql_exception(self._data)
  File "/usr/local/lib/python3.7/site-packages/pymysql/err.py", line 107, in raise_mysql_exception
    raise errorclass(errno, errval)
django.db.utils.ProgrammingError: (1146, "Table 'prj_sports.app_sumo_tran_banzuke_forecast' doesn't exist")
[WARNING]	2020-04-21 10:18:53,536	module:log	django.request.log_response:228	Not Found: /favicon.ico
[WARNING]	2020-04-21 10:18:55,738	module:log	django.request.log_response:228	Not Found: /favicon.ico
[WARNING]	2020-04-21 10:19:10,056	module:log	django.request.log_response:228	Not Found: /favicon.ico
[WARNING]	2020-04-21 10:19:30,773	module:log	django.request.log_response:228	Not Found: /favicon.ico
[WARNING]	2020-04-21 10:19:32,950	module:log	django.request.log_response:228	Not Found: /favicon.ico
[WARNING]	2020-04-21 10:19:47,025	module:log	django.request.log_response:228	Not Found: /favicon.ico
[WARNING]	2020-04-21 10:19:48,688	module:log	django.request.log_response:228	Not Found: /favicon.ico
[WARNING]	2020-04-21 10:20:01,397	module:log	django.request.log_response:228	Not Found: /favicon.ico
[WARNING]	2020-04-21 12:25:48,441	module:log	django.request.log_response:228	Not Found: /favicon.ico
[WARNING]	2020-04-21 12:25:58,172	module:log	django.request.log_response:228	Not Found: /favicon.ico
[ERROR]	2020-04-21 12:26:24,661	module:log	django.request.log_response:228	Internal Server Error: /admin/app_sumo/tran_yushosanshorikishi/
Traceback (most recent call last):
  File "/usr/local/lib/python3.7/site-packages/django/db/backends/utils.py", line 85, in _execute
    return self.cursor.execute(sql, params)
  File "/usr/local/lib/python3.7/site-packages/django/db/backends/mysql/base.py", line 71, in execute
    return self.cursor.execute(query, args)
  File "/usr/local/lib/python3.7/site-packages/pymysql/cursors.py", line 165, in execute
    result = self._query(query)
  File "/usr/local/lib/python3.7/site-packages/pymysql/cursors.py", line 321, in _query
    conn.query(q)
  File "/usr/local/lib/python3.7/site-packages/pymysql/connections.py", line 860, in query
    self._affected_rows = self._read_query_result(unbuffered=unbuffered)
  File "/usr/local/lib/python3.7/site-packages/pymysql/connections.py", line 1061, in _read_query_result
    result.read()
  File "/usr/local/lib/python3.7/site-packages/pymysql/connections.py", line 1349, in read
    first_packet = self.connection._read_packet()
  File "/usr/local/lib/python3.7/site-packages/pymysql/connections.py", line 1018, in _read_packet
    packet.check_error()
  File "/usr/local/lib/python3.7/site-packages/pymysql/connections.py", line 384, in check_error
    err.raise_mysql_exception(self._data)
  File "/usr/local/lib/python3.7/site-packages/pymysql/err.py", line 107, in raise_mysql_exception
    raise errorclass(errno, errval)
pymysql.err.ProgrammingError: (1146, "Table 'prj_sports.app_sumo_tran_yushosanshorikishi' doesn't exist")

The above exception was the direct cause of the following exception:

Traceback (most recent call last):
  File "/usr/local/lib/python3.7/site-packages/django/core/handlers/exception.py", line 34, in inner
    response = get_response(request)
  File "/usr/local/lib/python3.7/site-packages/django/core/handlers/base.py", line 126, in _get_response
    response = self.process_exception_by_middleware(e, request)
  File "/usr/local/lib/python3.7/site-packages/django/core/handlers/base.py", line 124, in _get_response
    response = wrapped_callback(request, *callback_args, **callback_kwargs)
  File "/usr/local/lib/python3.7/site-packages/django/contrib/admin/options.py", line 604, in wrapper
    return self.admin_site.admin_view(view)(*args, **kwargs)
  File "/usr/local/lib/python3.7/site-packages/django/utils/decorators.py", line 142, in _wrapped_view
    response = view_func(request, *args, **kwargs)
  File "/usr/local/lib/python3.7/site-packages/django/views/decorators/cache.py", line 44, in _wrapped_view_func
    response = view_func(request, *args, **kwargs)
  File "/usr/local/lib/python3.7/site-packages/django/contrib/admin/sites.py", line 223, in inner
    return view(request, *args, **kwargs)
  File "/usr/local/lib/python3.7/site-packages/django/utils/decorators.py", line 45, in _wrapper
    return bound_method(*args, **kwargs)
  File "/usr/local/lib/python3.7/site-packages/django/utils/decorators.py", line 142, in _wrapped_view
    response = view_func(request, *args, **kwargs)
  File "/usr/local/lib/python3.7/site-packages/django/contrib/admin/options.py", line 1675, in changelist_view
    cl = self.get_changelist_instance(request)
  File "/usr/local/lib/python3.7/site-packages/django/contrib/admin/options.py", line 742, in get_changelist_instance
    sortable_by,
  File "/usr/local/lib/python3.7/site-packages/django/contrib/admin/views/main.py", line 81, in __init__
    self.get_results(request)
  File "/usr/local/lib/python3.7/site-packages/django/contrib/admin/views/main.py", line 209, in get_results
    result_count = paginator.count
  File "/usr/local/lib/python3.7/site-packages/django/utils/functional.py", line 37, in __get__
    res = instance.__dict__[self.name] = self.func(instance)
  File "/usr/local/lib/python3.7/site-packages/django/core/paginator.py", line 87, in count
    return self.object_list.count()
  File "/usr/local/lib/python3.7/site-packages/django/db/models/query.py", line 383, in count
    return self.query.get_count(using=self.db)
  File "/usr/local/lib/python3.7/site-packages/django/db/models/sql/query.py", line 498, in get_count
    number = obj.get_aggregation(using, ['__count'])['__count']
  File "/usr/local/lib/python3.7/site-packages/django/db/models/sql/query.py", line 483, in get_aggregation
    result = compiler.execute_sql(SINGLE)
  File "/usr/local/lib/python3.7/site-packages/django/db/models/sql/compiler.py", line 1065, in execute_sql
    cursor.execute(sql, params)
  File "/usr/local/lib/python3.7/site-packages/django/db/backends/utils.py", line 100, in execute
    return super().execute(sql, params)
  File "/usr/local/lib/python3.7/site-packages/django/db/backends/utils.py", line 68, in execute
    return self._execute_with_wrappers(sql, params, many=False, executor=self._execute)
  File "/usr/local/lib/python3.7/site-packages/django/db/backends/utils.py", line 77, in _execute_with_wrappers
    return executor(sql, params, many, context)
  File "/usr/local/lib/python3.7/site-packages/django/db/backends/utils.py", line 85, in _execute
    return self.cursor.execute(sql, params)
  File "/usr/local/lib/python3.7/site-packages/django/db/utils.py", line 89, in __exit__
    raise dj_exc_value.with_traceback(traceback) from exc_value
  File "/usr/local/lib/python3.7/site-packages/django/db/backends/utils.py", line 85, in _execute
    return self.cursor.execute(sql, params)
  File "/usr/local/lib/python3.7/site-packages/django/db/backends/mysql/base.py", line 71, in execute
    return self.cursor.execute(query, args)
  File "/usr/local/lib/python3.7/site-packages/pymysql/cursors.py", line 165, in execute
    result = self._query(query)
  File "/usr/local/lib/python3.7/site-packages/pymysql/cursors.py", line 321, in _query
    conn.query(q)
  File "/usr/local/lib/python3.7/site-packages/pymysql/connections.py", line 860, in query
    self._affected_rows = self._read_query_result(unbuffered=unbuffered)
  File "/usr/local/lib/python3.7/site-packages/pymysql/connections.py", line 1061, in _read_query_result
    result.read()
  File "/usr/local/lib/python3.7/site-packages/pymysql/connections.py", line 1349, in read
    first_packet = self.connection._read_packet()
  File "/usr/local/lib/python3.7/site-packages/pymysql/connections.py", line 1018, in _read_packet
    packet.check_error()
  File "/usr/local/lib/python3.7/site-packages/pymysql/connections.py", line 384, in check_error
    err.raise_mysql_exception(self._data)
  File "/usr/local/lib/python3.7/site-packages/pymysql/err.py", line 107, in raise_mysql_exception
    raise errorclass(errno, errval)
django.db.utils.ProgrammingError: (1146, "Table 'prj_sports.app_sumo_tran_yushosanshorikishi' doesn't exist")
[WARNING]	2020-04-21 12:26:24,719	module:log	django.request.log_response:228	Not Found: /favicon.ico
[ERROR]	2020-04-21 12:28:55,089	module:log	django.request.log_response:228	Internal Server Error: /admin/app_sumo/tran_yushosanshorikishi/
Traceback (most recent call last):
  File "/usr/local/lib/python3.7/site-packages/django/db/backends/utils.py", line 85, in _execute
    return self.cursor.execute(sql, params)
  File "/usr/local/lib/python3.7/site-packages/django/db/backends/mysql/base.py", line 71, in execute
    return self.cursor.execute(query, args)
  File "/usr/local/lib/python3.7/site-packages/pymysql/cursors.py", line 165, in execute
    result = self._query(query)
  File "/usr/local/lib/python3.7/site-packages/pymysql/cursors.py", line 321, in _query
    conn.query(q)
  File "/usr/local/lib/python3.7/site-packages/pymysql/connections.py", line 860, in query
    self._affected_rows = self._read_query_result(unbuffered=unbuffered)
  File "/usr/local/lib/python3.7/site-packages/pymysql/connections.py", line 1061, in _read_query_result
    result.read()
  File "/usr/local/lib/python3.7/site-packages/pymysql/connections.py", line 1349, in read
    first_packet = self.connection._read_packet()
  File "/usr/local/lib/python3.7/site-packages/pymysql/connections.py", line 1018, in _read_packet
    packet.check_error()
  File "/usr/local/lib/python3.7/site-packages/pymysql/connections.py", line 384, in check_error
    err.raise_mysql_exception(self._data)
  File "/usr/local/lib/python3.7/site-packages/pymysql/err.py", line 107, in raise_mysql_exception
    raise errorclass(errno, errval)
pymysql.err.ProgrammingError: (1146, "Table 'prj_sports.app_sumo_tran_yushosanshorikishi' doesn't exist")

The above exception was the direct cause of the following exception:

Traceback (most recent call last):
  File "/usr/local/lib/python3.7/site-packages/django/core/handlers/exception.py", line 34, in inner
    response = get_response(request)
  File "/usr/local/lib/python3.7/site-packages/django/core/handlers/base.py", line 126, in _get_response
    response = self.process_exception_by_middleware(e, request)
  File "/usr/local/lib/python3.7/site-packages/django/core/handlers/base.py", line 124, in _get_response
    response = wrapped_callback(request, *callback_args, **callback_kwargs)
  File "/usr/local/lib/python3.7/site-packages/django/contrib/admin/options.py", line 604, in wrapper
    return self.admin_site.admin_view(view)(*args, **kwargs)
  File "/usr/local/lib/python3.7/site-packages/django/utils/decorators.py", line 142, in _wrapped_view
    response = view_func(request, *args, **kwargs)
  File "/usr/local/lib/python3.7/site-packages/django/views/decorators/cache.py", line 44, in _wrapped_view_func
    response = view_func(request, *args, **kwargs)
  File "/usr/local/lib/python3.7/site-packages/django/contrib/admin/sites.py", line 223, in inner
    return view(request, *args, **kwargs)
  File "/usr/local/lib/python3.7/site-packages/django/utils/decorators.py", line 45, in _wrapper
    return bound_method(*args, **kwargs)
  File "/usr/local/lib/python3.7/site-packages/django/utils/decorators.py", line 142, in _wrapped_view
    response = view_func(request, *args, **kwargs)
  File "/usr/local/lib/python3.7/site-packages/django/contrib/admin/options.py", line 1675, in changelist_view
    cl = self.get_changelist_instance(request)
  File "/usr/local/lib/python3.7/site-packages/django/contrib/admin/options.py", line 742, in get_changelist_instance
    sortable_by,
  File "/usr/local/lib/python3.7/site-packages/django/contrib/admin/views/main.py", line 81, in __init__
    self.get_results(request)
  File "/usr/local/lib/python3.7/site-packages/django/contrib/admin/views/main.py", line 209, in get_results
    result_count = paginator.count
  File "/usr/local/lib/python3.7/site-packages/django/utils/functional.py", line 37, in __get__
    res = instance.__dict__[self.name] = self.func(instance)
  File "/usr/local/lib/python3.7/site-packages/django/core/paginator.py", line 87, in count
    return self.object_list.count()
  File "/usr/local/lib/python3.7/site-packages/django/db/models/query.py", line 383, in count
    return self.query.get_count(using=self.db)
  File "/usr/local/lib/python3.7/site-packages/django/db/models/sql/query.py", line 498, in get_count
    number = obj.get_aggregation(using, ['__count'])['__count']
  File "/usr/local/lib/python3.7/site-packages/django/db/models/sql/query.py", line 483, in get_aggregation
    result = compiler.execute_sql(SINGLE)
  File "/usr/local/lib/python3.7/site-packages/django/db/models/sql/compiler.py", line 1065, in execute_sql
    cursor.execute(sql, params)
  File "/usr/local/lib/python3.7/site-packages/django/db/backends/utils.py", line 100, in execute
    return super().execute(sql, params)
  File "/usr/local/lib/python3.7/site-packages/django/db/backends/utils.py", line 68, in execute
    return self._execute_with_wrappers(sql, params, many=False, executor=self._execute)
  File "/usr/local/lib/python3.7/site-packages/django/db/backends/utils.py", line 77, in _execute_with_wrappers
    return executor(sql, params, many, context)
  File "/usr/local/lib/python3.7/site-packages/django/db/backends/utils.py", line 85, in _execute
    return self.cursor.execute(sql, params)
  File "/usr/local/lib/python3.7/site-packages/django/db/utils.py", line 89, in __exit__
    raise dj_exc_value.with_traceback(traceback) from exc_value
  File "/usr/local/lib/python3.7/site-packages/django/db/backends/utils.py", line 85, in _execute
    return self.cursor.execute(sql, params)
  File "/usr/local/lib/python3.7/site-packages/django/db/backends/mysql/base.py", line 71, in execute
    return self.cursor.execute(query, args)
  File "/usr/local/lib/python3.7/site-packages/pymysql/cursors.py", line 165, in execute
    result = self._query(query)
  File "/usr/local/lib/python3.7/site-packages/pymysql/cursors.py", line 321, in _query
    conn.query(q)
  File "/usr/local/lib/python3.7/site-packages/pymysql/connections.py", line 860, in query
    self._affected_rows = self._read_query_result(unbuffered=unbuffered)
  File "/usr/local/lib/python3.7/site-packages/pymysql/connections.py", line 1061, in _read_query_result
    result.read()
  File "/usr/local/lib/python3.7/site-packages/pymysql/connections.py", line 1349, in read
    first_packet = self.connection._read_packet()
  File "/usr/local/lib/python3.7/site-packages/pymysql/connections.py", line 1018, in _read_packet
    packet.check_error()
  File "/usr/local/lib/python3.7/site-packages/pymysql/connections.py", line 384, in check_error
    err.raise_mysql_exception(self._data)
  File "/usr/local/lib/python3.7/site-packages/pymysql/err.py", line 107, in raise_mysql_exception
    raise errorclass(errno, errval)
django.db.utils.ProgrammingError: (1146, "Table 'prj_sports.app_sumo_tran_yushosanshorikishi' doesn't exist")
[ERROR]	2020-04-21 12:29:00,525	module:log	django.request.log_response:228	Internal Server Error: /admin/app_sumo/tran_yushosanshorikishi/
Traceback (most recent call last):
  File "/usr/local/lib/python3.7/site-packages/django/db/backends/utils.py", line 85, in _execute
    return self.cursor.execute(sql, params)
  File "/usr/local/lib/python3.7/site-packages/django/db/backends/mysql/base.py", line 71, in execute
    return self.cursor.execute(query, args)
  File "/usr/local/lib/python3.7/site-packages/pymysql/cursors.py", line 165, in execute
    result = self._query(query)
  File "/usr/local/lib/python3.7/site-packages/pymysql/cursors.py", line 321, in _query
    conn.query(q)
  File "/usr/local/lib/python3.7/site-packages/pymysql/connections.py", line 860, in query
    self._affected_rows = self._read_query_result(unbuffered=unbuffered)
  File "/usr/local/lib/python3.7/site-packages/pymysql/connections.py", line 1061, in _read_query_result
    result.read()
  File "/usr/local/lib/python3.7/site-packages/pymysql/connections.py", line 1349, in read
    first_packet = self.connection._read_packet()
  File "/usr/local/lib/python3.7/site-packages/pymysql/connections.py", line 1018, in _read_packet
    packet.check_error()
  File "/usr/local/lib/python3.7/site-packages/pymysql/connections.py", line 384, in check_error
    err.raise_mysql_exception(self._data)
  File "/usr/local/lib/python3.7/site-packages/pymysql/err.py", line 107, in raise_mysql_exception
    raise errorclass(errno, errval)
pymysql.err.ProgrammingError: (1146, "Table 'prj_sports.app_sumo_tran_yushosanshorikishi' doesn't exist")

The above exception was the direct cause of the following exception:

Traceback (most recent call last):
  File "/usr/local/lib/python3.7/site-packages/django/core/handlers/exception.py", line 34, in inner
    response = get_response(request)
  File "/usr/local/lib/python3.7/site-packages/django/core/handlers/base.py", line 126, in _get_response
    response = self.process_exception_by_middleware(e, request)
  File "/usr/local/lib/python3.7/site-packages/django/core/handlers/base.py", line 124, in _get_response
    response = wrapped_callback(request, *callback_args, **callback_kwargs)
  File "/usr/local/lib/python3.7/site-packages/django/contrib/admin/options.py", line 604, in wrapper
    return self.admin_site.admin_view(view)(*args, **kwargs)
  File "/usr/local/lib/python3.7/site-packages/django/utils/decorators.py", line 142, in _wrapped_view
    response = view_func(request, *args, **kwargs)
  File "/usr/local/lib/python3.7/site-packages/django/views/decorators/cache.py", line 44, in _wrapped_view_func
    response = view_func(request, *args, **kwargs)
  File "/usr/local/lib/python3.7/site-packages/django/contrib/admin/sites.py", line 223, in inner
    return view(request, *args, **kwargs)
  File "/usr/local/lib/python3.7/site-packages/django/utils/decorators.py", line 45, in _wrapper
    return bound_method(*args, **kwargs)
  File "/usr/local/lib/python3.7/site-packages/django/utils/decorators.py", line 142, in _wrapped_view
    response = view_func(request, *args, **kwargs)
  File "/usr/local/lib/python3.7/site-packages/django/contrib/admin/options.py", line 1675, in changelist_view
    cl = self.get_changelist_instance(request)
  File "/usr/local/lib/python3.7/site-packages/django/contrib/admin/options.py", line 742, in get_changelist_instance
    sortable_by,
  File "/usr/local/lib/python3.7/site-packages/django/contrib/admin/views/main.py", line 81, in __init__
    self.get_results(request)
  File "/usr/local/lib/python3.7/site-packages/django/contrib/admin/views/main.py", line 209, in get_results
    result_count = paginator.count
  File "/usr/local/lib/python3.7/site-packages/django/utils/functional.py", line 37, in __get__
    res = instance.__dict__[self.name] = self.func(instance)
  File "/usr/local/lib/python3.7/site-packages/django/core/paginator.py", line 87, in count
    return self.object_list.count()
  File "/usr/local/lib/python3.7/site-packages/django/db/models/query.py", line 383, in count
    return self.query.get_count(using=self.db)
  File "/usr/local/lib/python3.7/site-packages/django/db/models/sql/query.py", line 498, in get_count
    number = obj.get_aggregation(using, ['__count'])['__count']
  File "/usr/local/lib/python3.7/site-packages/django/db/models/sql/query.py", line 483, in get_aggregation
    result = compiler.execute_sql(SINGLE)
  File "/usr/local/lib/python3.7/site-packages/django/db/models/sql/compiler.py", line 1065, in execute_sql
    cursor.execute(sql, params)
  File "/usr/local/lib/python3.7/site-packages/django/db/backends/utils.py", line 100, in execute
    return super().execute(sql, params)
  File "/usr/local/lib/python3.7/site-packages/django/db/backends/utils.py", line 68, in execute
    return self._execute_with_wrappers(sql, params, many=False, executor=self._execute)
  File "/usr/local/lib/python3.7/site-packages/django/db/backends/utils.py", line 77, in _execute_with_wrappers
    return executor(sql, params, many, context)
  File "/usr/local/lib/python3.7/site-packages/django/db/backends/utils.py", line 85, in _execute
    return self.cursor.execute(sql, params)
  File "/usr/local/lib/python3.7/site-packages/django/db/utils.py", line 89, in __exit__
    raise dj_exc_value.with_traceback(traceback) from exc_value
  File "/usr/local/lib/python3.7/site-packages/django/db/backends/utils.py", line 85, in _execute
    return self.cursor.execute(sql, params)
  File "/usr/local/lib/python3.7/site-packages/django/db/backends/mysql/base.py", line 71, in execute
    return self.cursor.execute(query, args)
  File "/usr/local/lib/python3.7/site-packages/pymysql/cursors.py", line 165, in execute
    result = self._query(query)
  File "/usr/local/lib/python3.7/site-packages/pymysql/cursors.py", line 321, in _query
    conn.query(q)
  File "/usr/local/lib/python3.7/site-packages/pymysql/connections.py", line 860, in query
    self._affected_rows = self._read_query_result(unbuffered=unbuffered)
  File "/usr/local/lib/python3.7/site-packages/pymysql/connections.py", line 1061, in _read_query_result
    result.read()
  File "/usr/local/lib/python3.7/site-packages/pymysql/connections.py", line 1349, in read
    first_packet = self.connection._read_packet()
  File "/usr/local/lib/python3.7/site-packages/pymysql/connections.py", line 1018, in _read_packet
    packet.check_error()
  File "/usr/local/lib/python3.7/site-packages/pymysql/connections.py", line 384, in check_error
    err.raise_mysql_exception(self._data)
  File "/usr/local/lib/python3.7/site-packages/pymysql/err.py", line 107, in raise_mysql_exception
    raise errorclass(errno, errval)
django.db.utils.ProgrammingError: (1146, "Table 'prj_sports.app_sumo_tran_yushosanshorikishi' doesn't exist")
[ERROR]	2020-04-21 12:29:51,575	module:log	django.request.log_response:228	Internal Server Error: /admin/app_sumo/tran_yushosanshorikishi/
Traceback (most recent call last):
  File "/usr/local/lib/python3.7/site-packages/django/db/backends/utils.py", line 85, in _execute
    return self.cursor.execute(sql, params)
  File "/usr/local/lib/python3.7/site-packages/django/db/backends/mysql/base.py", line 71, in execute
    return self.cursor.execute(query, args)
  File "/usr/local/lib/python3.7/site-packages/pymysql/cursors.py", line 165, in execute
    result = self._query(query)
  File "/usr/local/lib/python3.7/site-packages/pymysql/cursors.py", line 321, in _query
    conn.query(q)
  File "/usr/local/lib/python3.7/site-packages/pymysql/connections.py", line 860, in query
    self._affected_rows = self._read_query_result(unbuffered=unbuffered)
  File "/usr/local/lib/python3.7/site-packages/pymysql/connections.py", line 1061, in _read_query_result
    result.read()
  File "/usr/local/lib/python3.7/site-packages/pymysql/connections.py", line 1349, in read
    first_packet = self.connection._read_packet()
  File "/usr/local/lib/python3.7/site-packages/pymysql/connections.py", line 1018, in _read_packet
    packet.check_error()
  File "/usr/local/lib/python3.7/site-packages/pymysql/connections.py", line 384, in check_error
    err.raise_mysql_exception(self._data)
  File "/usr/local/lib/python3.7/site-packages/pymysql/err.py", line 107, in raise_mysql_exception
    raise errorclass(errno, errval)
pymysql.err.ProgrammingError: (1146, "Table 'prj_sports.app_sumo_tran_yushosanshorikishi' doesn't exist")

The above exception was the direct cause of the following exception:

Traceback (most recent call last):
  File "/usr/local/lib/python3.7/site-packages/django/core/handlers/exception.py", line 34, in inner
    response = get_response(request)
  File "/usr/local/lib/python3.7/site-packages/django/core/handlers/base.py", line 126, in _get_response
    response = self.process_exception_by_middleware(e, request)
  File "/usr/local/lib/python3.7/site-packages/django/core/handlers/base.py", line 124, in _get_response
    response = wrapped_callback(request, *callback_args, **callback_kwargs)
  File "/usr/local/lib/python3.7/site-packages/django/contrib/admin/options.py", line 604, in wrapper
    return self.admin_site.admin_view(view)(*args, **kwargs)
  File "/usr/local/lib/python3.7/site-packages/django/utils/decorators.py", line 142, in _wrapped_view
    response = view_func(request, *args, **kwargs)
  File "/usr/local/lib/python3.7/site-packages/django/views/decorators/cache.py", line 44, in _wrapped_view_func
    response = view_func(request, *args, **kwargs)
  File "/usr/local/lib/python3.7/site-packages/django/contrib/admin/sites.py", line 223, in inner
    return view(request, *args, **kwargs)
  File "/usr/local/lib/python3.7/site-packages/django/utils/decorators.py", line 45, in _wrapper
    return bound_method(*args, **kwargs)
  File "/usr/local/lib/python3.7/site-packages/django/utils/decorators.py", line 142, in _wrapped_view
    response = view_func(request, *args, **kwargs)
  File "/usr/local/lib/python3.7/site-packages/django/contrib/admin/options.py", line 1675, in changelist_view
    cl = self.get_changelist_instance(request)
  File "/usr/local/lib/python3.7/site-packages/django/contrib/admin/options.py", line 742, in get_changelist_instance
    sortable_by,
  File "/usr/local/lib/python3.7/site-packages/django/contrib/admin/views/main.py", line 81, in __init__
    self.get_results(request)
  File "/usr/local/lib/python3.7/site-packages/django/contrib/admin/views/main.py", line 209, in get_results
    result_count = paginator.count
  File "/usr/local/lib/python3.7/site-packages/django/utils/functional.py", line 37, in __get__
    res = instance.__dict__[self.name] = self.func(instance)
  File "/usr/local/lib/python3.7/site-packages/django/core/paginator.py", line 87, in count
    return self.object_list.count()
  File "/usr/local/lib/python3.7/site-packages/django/db/models/query.py", line 383, in count
    return self.query.get_count(using=self.db)
  File "/usr/local/lib/python3.7/site-packages/django/db/models/sql/query.py", line 498, in get_count
    number = obj.get_aggregation(using, ['__count'])['__count']
  File "/usr/local/lib/python3.7/site-packages/django/db/models/sql/query.py", line 483, in get_aggregation
    result = compiler.execute_sql(SINGLE)
  File "/usr/local/lib/python3.7/site-packages/django/db/models/sql/compiler.py", line 1065, in execute_sql
    cursor.execute(sql, params)
  File "/usr/local/lib/python3.7/site-packages/django/db/backends/utils.py", line 100, in execute
    return super().execute(sql, params)
  File "/usr/local/lib/python3.7/site-packages/django/db/backends/utils.py", line 68, in execute
    return self._execute_with_wrappers(sql, params, many=False, executor=self._execute)
  File "/usr/local/lib/python3.7/site-packages/django/db/backends/utils.py", line 77, in _execute_with_wrappers
    return executor(sql, params, many, context)
  File "/usr/local/lib/python3.7/site-packages/django/db/backends/utils.py", line 85, in _execute
    return self.cursor.execute(sql, params)
  File "/usr/local/lib/python3.7/site-packages/django/db/utils.py", line 89, in __exit__
    raise dj_exc_value.with_traceback(traceback) from exc_value
  File "/usr/local/lib/python3.7/site-packages/django/db/backends/utils.py", line 85, in _execute
    return self.cursor.execute(sql, params)
  File "/usr/local/lib/python3.7/site-packages/django/db/backends/mysql/base.py", line 71, in execute
    return self.cursor.execute(query, args)
  File "/usr/local/lib/python3.7/site-packages/pymysql/cursors.py", line 165, in execute
    result = self._query(query)
  File "/usr/local/lib/python3.7/site-packages/pymysql/cursors.py", line 321, in _query
    conn.query(q)
  File "/usr/local/lib/python3.7/site-packages/pymysql/connections.py", line 860, in query
    self._affected_rows = self._read_query_result(unbuffered=unbuffered)
  File "/usr/local/lib/python3.7/site-packages/pymysql/connections.py", line 1061, in _read_query_result
    result.read()
  File "/usr/local/lib/python3.7/site-packages/pymysql/connections.py", line 1349, in read
    first_packet = self.connection._read_packet()
  File "/usr/local/lib/python3.7/site-packages/pymysql/connections.py", line 1018, in _read_packet
    packet.check_error()
  File "/usr/local/lib/python3.7/site-packages/pymysql/connections.py", line 384, in check_error
    err.raise_mysql_exception(self._data)
  File "/usr/local/lib/python3.7/site-packages/pymysql/err.py", line 107, in raise_mysql_exception
    raise errorclass(errno, errval)
django.db.utils.ProgrammingError: (1146, "Table 'prj_sports.app_sumo_tran_yushosanshorikishi' doesn't exist")
[WARNING]	2020-04-21 12:30:00,092	module:log	django.request.log_response:228	Not Found: /favicon.ico
[ERROR]	2020-04-21 12:30:04,382	module:log	django.request.log_response:228	Internal Server Error: /admin/app_sumo/tran_yushosanshorikishi/
Traceback (most recent call last):
  File "/usr/local/lib/python3.7/site-packages/django/db/backends/utils.py", line 85, in _execute
    return self.cursor.execute(sql, params)
  File "/usr/local/lib/python3.7/site-packages/django/db/backends/mysql/base.py", line 71, in execute
    return self.cursor.execute(query, args)
  File "/usr/local/lib/python3.7/site-packages/pymysql/cursors.py", line 165, in execute
    result = self._query(query)
  File "/usr/local/lib/python3.7/site-packages/pymysql/cursors.py", line 321, in _query
    conn.query(q)
  File "/usr/local/lib/python3.7/site-packages/pymysql/connections.py", line 860, in query
    self._affected_rows = self._read_query_result(unbuffered=unbuffered)
  File "/usr/local/lib/python3.7/site-packages/pymysql/connections.py", line 1061, in _read_query_result
    result.read()
  File "/usr/local/lib/python3.7/site-packages/pymysql/connections.py", line 1349, in read
    first_packet = self.connection._read_packet()
  File "/usr/local/lib/python3.7/site-packages/pymysql/connections.py", line 1018, in _read_packet
    packet.check_error()
  File "/usr/local/lib/python3.7/site-packages/pymysql/connections.py", line 384, in check_error
    err.raise_mysql_exception(self._data)
  File "/usr/local/lib/python3.7/site-packages/pymysql/err.py", line 107, in raise_mysql_exception
    raise errorclass(errno, errval)
pymysql.err.ProgrammingError: (1146, "Table 'prj_sports.app_sumo_tran_yushosanshorikishi' doesn't exist")

The above exception was the direct cause of the following exception:

Traceback (most recent call last):
  File "/usr/local/lib/python3.7/site-packages/django/core/handlers/exception.py", line 34, in inner
    response = get_response(request)
  File "/usr/local/lib/python3.7/site-packages/django/core/handlers/base.py", line 126, in _get_response
    response = self.process_exception_by_middleware(e, request)
  File "/usr/local/lib/python3.7/site-packages/django/core/handlers/base.py", line 124, in _get_response
    response = wrapped_callback(request, *callback_args, **callback_kwargs)
  File "/usr/local/lib/python3.7/site-packages/django/contrib/admin/options.py", line 604, in wrapper
    return self.admin_site.admin_view(view)(*args, **kwargs)
  File "/usr/local/lib/python3.7/site-packages/django/utils/decorators.py", line 142, in _wrapped_view
    response = view_func(request, *args, **kwargs)
  File "/usr/local/lib/python3.7/site-packages/django/views/decorators/cache.py", line 44, in _wrapped_view_func
    response = view_func(request, *args, **kwargs)
  File "/usr/local/lib/python3.7/site-packages/django/contrib/admin/sites.py", line 223, in inner
    return view(request, *args, **kwargs)
  File "/usr/local/lib/python3.7/site-packages/django/utils/decorators.py", line 45, in _wrapper
    return bound_method(*args, **kwargs)
  File "/usr/local/lib/python3.7/site-packages/django/utils/decorators.py", line 142, in _wrapped_view
    response = view_func(request, *args, **kwargs)
  File "/usr/local/lib/python3.7/site-packages/django/contrib/admin/options.py", line 1675, in changelist_view
    cl = self.get_changelist_instance(request)
  File "/usr/local/lib/python3.7/site-packages/django/contrib/admin/options.py", line 742, in get_changelist_instance
    sortable_by,
  File "/usr/local/lib/python3.7/site-packages/django/contrib/admin/views/main.py", line 81, in __init__
    self.get_results(request)
  File "/usr/local/lib/python3.7/site-packages/django/contrib/admin/views/main.py", line 209, in get_results
    result_count = paginator.count
  File "/usr/local/lib/python3.7/site-packages/django/utils/functional.py", line 37, in __get__
    res = instance.__dict__[self.name] = self.func(instance)
  File "/usr/local/lib/python3.7/site-packages/django/core/paginator.py", line 87, in count
    return self.object_list.count()
  File "/usr/local/lib/python3.7/site-packages/django/db/models/query.py", line 383, in count
    return self.query.get_count(using=self.db)
  File "/usr/local/lib/python3.7/site-packages/django/db/models/sql/query.py", line 498, in get_count
    number = obj.get_aggregation(using, ['__count'])['__count']
  File "/usr/local/lib/python3.7/site-packages/django/db/models/sql/query.py", line 483, in get_aggregation
    result = compiler.execute_sql(SINGLE)
  File "/usr/local/lib/python3.7/site-packages/django/db/models/sql/compiler.py", line 1065, in execute_sql
    cursor.execute(sql, params)
  File "/usr/local/lib/python3.7/site-packages/django/db/backends/utils.py", line 100, in execute
    return super().execute(sql, params)
  File "/usr/local/lib/python3.7/site-packages/django/db/backends/utils.py", line 68, in execute
    return self._execute_with_wrappers(sql, params, many=False, executor=self._execute)
  File "/usr/local/lib/python3.7/site-packages/django/db/backends/utils.py", line 77, in _execute_with_wrappers
    return executor(sql, params, many, context)
  File "/usr/local/lib/python3.7/site-packages/django/db/backends/utils.py", line 85, in _execute
    return self.cursor.execute(sql, params)
  File "/usr/local/lib/python3.7/site-packages/django/db/utils.py", line 89, in __exit__
    raise dj_exc_value.with_traceback(traceback) from exc_value
  File "/usr/local/lib/python3.7/site-packages/django/db/backends/utils.py", line 85, in _execute
    return self.cursor.execute(sql, params)
  File "/usr/local/lib/python3.7/site-packages/django/db/backends/mysql/base.py", line 71, in execute
    return self.cursor.execute(query, args)
  File "/usr/local/lib/python3.7/site-packages/pymysql/cursors.py", line 165, in execute
    result = self._query(query)
  File "/usr/local/lib/python3.7/site-packages/pymysql/cursors.py", line 321, in _query
    conn.query(q)
  File "/usr/local/lib/python3.7/site-packages/pymysql/connections.py", line 860, in query
    self._affected_rows = self._read_query_result(unbuffered=unbuffered)
  File "/usr/local/lib/python3.7/site-packages/pymysql/connections.py", line 1061, in _read_query_result
    result.read()
  File "/usr/local/lib/python3.7/site-packages/pymysql/connections.py", line 1349, in read
    first_packet = self.connection._read_packet()
  File "/usr/local/lib/python3.7/site-packages/pymysql/connections.py", line 1018, in _read_packet
    packet.check_error()
  File "/usr/local/lib/python3.7/site-packages/pymysql/connections.py", line 384, in check_error
    err.raise_mysql_exception(self._data)
  File "/usr/local/lib/python3.7/site-packages/pymysql/err.py", line 107, in raise_mysql_exception
    raise errorclass(errno, errval)
django.db.utils.ProgrammingError: (1146, "Table 'prj_sports.app_sumo_tran_yushosanshorikishi' doesn't exist")
[WARNING]	2020-04-21 12:34:45,724	module:log	django.request.log_response:228	Not Found: /favicon.ico
[WARNING]	2020-04-21 12:34:48,280	module:log	django.request.log_response:228	Not Found: /favicon.ico
[WARNING]	2020-04-21 12:35:27,914	module:log	django.request.log_response:228	Not Found: /favicon.ico
[WARNING]	2020-04-21 12:35:31,695	module:log	django.request.log_response:228	Not Found: /favicon.ico
[WARNING]	2020-04-21 12:42:01,355	module:log	django.request.log_response:228	Not Found: /favicon.ico
[WARNING]	2020-04-21 12:43:55,654	module:log	django.request.log_response:228	Not Found: /favicon.ico
[WARNING]	2020-04-21 12:47:28,926	module:log	django.request.log_response:228	Not Found: /favicon.ico
[WARNING]	2020-04-21 12:59:13,600	module:log	django.request.log_response:228	Not Found: /favicon.ico
[ERROR]	2020-04-21 13:01:59,823	module:log	django.request.log_response:228	Internal Server Error: /admin/app_sumo/tran_yushosansho/
Traceback (most recent call last):
  File "/usr/local/lib/python3.7/site-packages/django/db/models/options.py", line 564, in get_field
    return self.fields_map[field_name]
KeyError: 'Rikishi_code'

During handling of the above exception, another exception occurred:

Traceback (most recent call last):
  File "/usr/local/lib/python3.7/site-packages/django/contrib/admin/utils.py", line 332, in label_for_field
    field = _get_non_gfk_field(model._meta, name)
  File "/usr/local/lib/python3.7/site-packages/django/contrib/admin/utils.py", line 309, in _get_non_gfk_field
    field = opts.get_field(name)
  File "/usr/local/lib/python3.7/site-packages/django/db/models/options.py", line 566, in get_field
    raise FieldDoesNotExist("%s has no field named '%s'" % (self.object_name, field_name))
django.core.exceptions.FieldDoesNotExist: Tran_YushoSansho has no field named 'Rikishi_code'

During handling of the above exception, another exception occurred:

Traceback (most recent call last):
  File "/usr/local/lib/python3.7/site-packages/django/core/handlers/exception.py", line 34, in inner
    response = get_response(request)
  File "/usr/local/lib/python3.7/site-packages/django/core/handlers/base.py", line 156, in _get_response
    response = self.process_exception_by_middleware(e, request)
  File "/usr/local/lib/python3.7/site-packages/django/core/handlers/base.py", line 154, in _get_response
    response = response.render()
  File "/usr/local/lib/python3.7/site-packages/django/template/response.py", line 106, in render
    self.content = self.rendered_content
  File "/usr/local/lib/python3.7/site-packages/django/template/response.py", line 83, in rendered_content
    content = template.render(context, self._request)
  File "/usr/local/lib/python3.7/site-packages/django/template/backends/django.py", line 61, in render
    return self.template.render(context)
  File "/usr/local/lib/python3.7/site-packages/django/template/base.py", line 171, in render
    return self._render(context)
  File "/usr/local/lib/python3.7/site-packages/django/template/base.py", line 163, in _render
    return self.nodelist.render(context)
  File "/usr/local/lib/python3.7/site-packages/django/template/base.py", line 937, in render
    bit = node.render_annotated(context)
  File "/usr/local/lib/python3.7/site-packages/django/template/base.py", line 904, in render_annotated
    return self.render(context)
  File "/usr/local/lib/python3.7/site-packages/django/template/loader_tags.py", line 150, in render
    return compiled_parent._render(context)
  File "/usr/local/lib/python3.7/site-packages/django/template/base.py", line 163, in _render
    return self.nodelist.render(context)
  File "/usr/local/lib/python3.7/site-packages/django/template/base.py", line 937, in render
    bit = node.render_annotated(context)
  File "/usr/local/lib/python3.7/site-packages/django/template/base.py", line 904, in render_annotated
    return self.render(context)
  File "/usr/local/lib/python3.7/site-packages/django/template/loader_tags.py", line 150, in render
    return compiled_parent._render(context)
  File "/usr/local/lib/python3.7/site-packages/django/template/base.py", line 163, in _render
    return self.nodelist.render(context)
  File "/usr/local/lib/python3.7/site-packages/django/template/base.py", line 937, in render
    bit = node.render_annotated(context)
  File "/usr/local/lib/python3.7/site-packages/django/template/base.py", line 904, in render_annotated
    return self.render(context)
  File "/usr/local/lib/python3.7/site-packages/django/template/loader_tags.py", line 62, in render
    result = block.nodelist.render(context)
  File "/usr/local/lib/python3.7/site-packages/django/template/base.py", line 937, in render
    bit = node.render_annotated(context)
  File "/usr/local/lib/python3.7/site-packages/django/template/base.py", line 904, in render_annotated
    return self.render(context)
  File "/usr/local/lib/python3.7/site-packages/django/template/loader_tags.py", line 62, in render
    result = block.nodelist.render(context)
  File "/usr/local/lib/python3.7/site-packages/django/template/base.py", line 937, in render
    bit = node.render_annotated(context)
  File "/usr/local/lib/python3.7/site-packages/django/template/base.py", line 904, in render_annotated
    return self.render(context)
  File "/usr/local/lib/python3.7/site-packages/django/contrib/admin/templatetags/base.py", line 33, in render
    return super().render(context)
  File "/usr/local/lib/python3.7/site-packages/django/template/library.py", line 214, in render
    _dict = self.func(*resolved_args, **resolved_kwargs)
  File "/usr/local/lib/python3.7/site-packages/django/contrib/admin/templatetags/admin_list.py", line 332, in result_list
    headers = list(result_headers(cl))
  File "/usr/local/lib/python3.7/site-packages/django/contrib/admin/templatetags/admin_list.py", line 112, in result_headers
    return_attr=True
  File "/usr/local/lib/python3.7/site-packages/django/contrib/admin/utils.py", line 357, in label_for_field
    raise AttributeError(message)
AttributeError: Unable to lookup 'Rikishi_code' on Tran_YushoSansho or Tran_YushoSanshoAdmin
[ERROR]	2020-04-21 13:02:02,921	module:log	django.request.log_response:228	Internal Server Error: /admin/app_sumo/tran_yushosansho/
Traceback (most recent call last):
  File "/usr/local/lib/python3.7/site-packages/django/db/models/options.py", line 564, in get_field
    return self.fields_map[field_name]
KeyError: 'Rikishi_code'

During handling of the above exception, another exception occurred:

Traceback (most recent call last):
  File "/usr/local/lib/python3.7/site-packages/django/contrib/admin/utils.py", line 332, in label_for_field
    field = _get_non_gfk_field(model._meta, name)
  File "/usr/local/lib/python3.7/site-packages/django/contrib/admin/utils.py", line 309, in _get_non_gfk_field
    field = opts.get_field(name)
  File "/usr/local/lib/python3.7/site-packages/django/db/models/options.py", line 566, in get_field
    raise FieldDoesNotExist("%s has no field named '%s'" % (self.object_name, field_name))
django.core.exceptions.FieldDoesNotExist: Tran_YushoSansho has no field named 'Rikishi_code'

During handling of the above exception, another exception occurred:

Traceback (most recent call last):
  File "/usr/local/lib/python3.7/site-packages/django/core/handlers/exception.py", line 34, in inner
    response = get_response(request)
  File "/usr/local/lib/python3.7/site-packages/django/core/handlers/base.py", line 156, in _get_response
    response = self.process_exception_by_middleware(e, request)
  File "/usr/local/lib/python3.7/site-packages/django/core/handlers/base.py", line 154, in _get_response
    response = response.render()
  File "/usr/local/lib/python3.7/site-packages/django/template/response.py", line 106, in render
    self.content = self.rendered_content
  File "/usr/local/lib/python3.7/site-packages/django/template/response.py", line 83, in rendered_content
    content = template.render(context, self._request)
  File "/usr/local/lib/python3.7/site-packages/django/template/backends/django.py", line 61, in render
    return self.template.render(context)
  File "/usr/local/lib/python3.7/site-packages/django/template/base.py", line 171, in render
    return self._render(context)
  File "/usr/local/lib/python3.7/site-packages/django/template/base.py", line 163, in _render
    return self.nodelist.render(context)
  File "/usr/local/lib/python3.7/site-packages/django/template/base.py", line 937, in render
    bit = node.render_annotated(context)
  File "/usr/local/lib/python3.7/site-packages/django/template/base.py", line 904, in render_annotated
    return self.render(context)
  File "/usr/local/lib/python3.7/site-packages/django/template/loader_tags.py", line 150, in render
    return compiled_parent._render(context)
  File "/usr/local/lib/python3.7/site-packages/django/template/base.py", line 163, in _render
    return self.nodelist.render(context)
  File "/usr/local/lib/python3.7/site-packages/django/template/base.py", line 937, in render
    bit = node.render_annotated(context)
  File "/usr/local/lib/python3.7/site-packages/django/template/base.py", line 904, in render_annotated
    return self.render(context)
  File "/usr/local/lib/python3.7/site-packages/django/template/loader_tags.py", line 150, in render
    return compiled_parent._render(context)
  File "/usr/local/lib/python3.7/site-packages/django/template/base.py", line 163, in _render
    return self.nodelist.render(context)
  File "/usr/local/lib/python3.7/site-packages/django/template/base.py", line 937, in render
    bit = node.render_annotated(context)
  File "/usr/local/lib/python3.7/site-packages/django/template/base.py", line 904, in render_annotated
    return self.render(context)
  File "/usr/local/lib/python3.7/site-packages/django/template/loader_tags.py", line 62, in render
    result = block.nodelist.render(context)
  File "/usr/local/lib/python3.7/site-packages/django/template/base.py", line 937, in render
    bit = node.render_annotated(context)
  File "/usr/local/lib/python3.7/site-packages/django/template/base.py", line 904, in render_annotated
    return self.render(context)
  File "/usr/local/lib/python3.7/site-packages/django/template/loader_tags.py", line 62, in render
    result = block.nodelist.render(context)
  File "/usr/local/lib/python3.7/site-packages/django/template/base.py", line 937, in render
    bit = node.render_annotated(context)
  File "/usr/local/lib/python3.7/site-packages/django/template/base.py", line 904, in render_annotated
    return self.render(context)
  File "/usr/local/lib/python3.7/site-packages/django/contrib/admin/templatetags/base.py", line 33, in render
    return super().render(context)
  File "/usr/local/lib/python3.7/site-packages/django/template/library.py", line 214, in render
    _dict = self.func(*resolved_args, **resolved_kwargs)
  File "/usr/local/lib/python3.7/site-packages/django/contrib/admin/templatetags/admin_list.py", line 332, in result_list
    headers = list(result_headers(cl))
  File "/usr/local/lib/python3.7/site-packages/django/contrib/admin/templatetags/admin_list.py", line 112, in result_headers
    return_attr=True
  File "/usr/local/lib/python3.7/site-packages/django/contrib/admin/utils.py", line 357, in label_for_field
    raise AttributeError(message)
AttributeError: Unable to lookup 'Rikishi_code' on Tran_YushoSansho or Tran_YushoSanshoAdmin
[ERROR]	2020-04-21 13:02:06,305	module:log	django.request.log_response:228	Internal Server Error: /admin/app_sumo/tran_yushosansho/
Traceback (most recent call last):
  File "/usr/local/lib/python3.7/site-packages/django/db/models/options.py", line 564, in get_field
    return self.fields_map[field_name]
KeyError: 'Rikishi_code'

During handling of the above exception, another exception occurred:

Traceback (most recent call last):
  File "/usr/local/lib/python3.7/site-packages/django/contrib/admin/utils.py", line 332, in label_for_field
    field = _get_non_gfk_field(model._meta, name)
  File "/usr/local/lib/python3.7/site-packages/django/contrib/admin/utils.py", line 309, in _get_non_gfk_field
    field = opts.get_field(name)
  File "/usr/local/lib/python3.7/site-packages/django/db/models/options.py", line 566, in get_field
    raise FieldDoesNotExist("%s has no field named '%s'" % (self.object_name, field_name))
django.core.exceptions.FieldDoesNotExist: Tran_YushoSansho has no field named 'Rikishi_code'

During handling of the above exception, another exception occurred:

Traceback (most recent call last):
  File "/usr/local/lib/python3.7/site-packages/django/core/handlers/exception.py", line 34, in inner
    response = get_response(request)
  File "/usr/local/lib/python3.7/site-packages/django/core/handlers/base.py", line 156, in _get_response
    response = self.process_exception_by_middleware(e, request)
  File "/usr/local/lib/python3.7/site-packages/django/core/handlers/base.py", line 154, in _get_response
    response = response.render()
  File "/usr/local/lib/python3.7/site-packages/django/template/response.py", line 106, in render
    self.content = self.rendered_content
  File "/usr/local/lib/python3.7/site-packages/django/template/response.py", line 83, in rendered_content
    content = template.render(context, self._request)
  File "/usr/local/lib/python3.7/site-packages/django/template/backends/django.py", line 61, in render
    return self.template.render(context)
  File "/usr/local/lib/python3.7/site-packages/django/template/base.py", line 171, in render
    return self._render(context)
  File "/usr/local/lib/python3.7/site-packages/django/template/base.py", line 163, in _render
    return self.nodelist.render(context)
  File "/usr/local/lib/python3.7/site-packages/django/template/base.py", line 937, in render
    bit = node.render_annotated(context)
  File "/usr/local/lib/python3.7/site-packages/django/template/base.py", line 904, in render_annotated
    return self.render(context)
  File "/usr/local/lib/python3.7/site-packages/django/template/loader_tags.py", line 150, in render
    return compiled_parent._render(context)
  File "/usr/local/lib/python3.7/site-packages/django/template/base.py", line 163, in _render
    return self.nodelist.render(context)
  File "/usr/local/lib/python3.7/site-packages/django/template/base.py", line 937, in render
    bit = node.render_annotated(context)
  File "/usr/local/lib/python3.7/site-packages/django/template/base.py", line 904, in render_annotated
    return self.render(context)
  File "/usr/local/lib/python3.7/site-packages/django/template/loader_tags.py", line 150, in render
    return compiled_parent._render(context)
  File "/usr/local/lib/python3.7/site-packages/django/template/base.py", line 163, in _render
    return self.nodelist.render(context)
  File "/usr/local/lib/python3.7/site-packages/django/template/base.py", line 937, in render
    bit = node.render_annotated(context)
  File "/usr/local/lib/python3.7/site-packages/django/template/base.py", line 904, in render_annotated
    return self.render(context)
  File "/usr/local/lib/python3.7/site-packages/django/template/loader_tags.py", line 62, in render
    result = block.nodelist.render(context)
  File "/usr/local/lib/python3.7/site-packages/django/template/base.py", line 937, in render
    bit = node.render_annotated(context)
  File "/usr/local/lib/python3.7/site-packages/django/template/base.py", line 904, in render_annotated
    return self.render(context)
  File "/usr/local/lib/python3.7/site-packages/django/template/loader_tags.py", line 62, in render
    result = block.nodelist.render(context)
  File "/usr/local/lib/python3.7/site-packages/django/template/base.py", line 937, in render
    bit = node.render_annotated(context)
  File "/usr/local/lib/python3.7/site-packages/django/template/base.py", line 904, in render_annotated
    return self.render(context)
  File "/usr/local/lib/python3.7/site-packages/django/contrib/admin/templatetags/base.py", line 33, in render
    return super().render(context)
  File "/usr/local/lib/python3.7/site-packages/django/template/library.py", line 214, in render
    _dict = self.func(*resolved_args, **resolved_kwargs)
  File "/usr/local/lib/python3.7/site-packages/django/contrib/admin/templatetags/admin_list.py", line 332, in result_list
    headers = list(result_headers(cl))
  File "/usr/local/lib/python3.7/site-packages/django/contrib/admin/templatetags/admin_list.py", line 112, in result_headers
    return_attr=True
  File "/usr/local/lib/python3.7/site-packages/django/contrib/admin/utils.py", line 357, in label_for_field
    raise AttributeError(message)
AttributeError: Unable to lookup 'Rikishi_code' on Tran_YushoSansho or Tran_YushoSanshoAdmin
[WARNING]	2020-04-21 13:04:46,171	module:log	django.request.log_response:228	Not Found: /favicon.ico
[WARNING]	2020-04-21 13:11:11,284	module:log	django.request.log_response:228	Not Found: /favicon.ico
[WARNING]	2020-04-21 13:11:12,898	module:log	django.request.log_response:228	Not Found: /favicon.ico
[WARNING]	2020-04-21 13:11:14,912	module:log	django.request.log_response:228	Not Found: /favicon.ico
[WARNING]	2020-04-21 13:11:16,240	module:log	django.request.log_response:228	Not Found: /favicon.ico
[WARNING]	2020-04-21 13:11:17,015	module:log	django.request.log_response:228	Not Found: /favicon.ico
[WARNING]	2020-04-21 13:11:30,054	module:log	django.request.log_response:228	Not Found: /favicon.ico
[WARNING]	2020-04-21 13:11:31,859	module:log	django.request.log_response:228	Not Found: /favicon.ico
[WARNING]	2020-04-21 13:11:33,192	module:log	django.request.log_response:228	Not Found: /favicon.ico
[WARNING]	2020-04-21 13:11:38,366	module:log	django.request.log_response:228	Not Found: /favicon.ico
[WARNING]	2020-04-21 13:11:50,845	module:log	django.request.log_response:228	Not Found: /favicon.ico
[WARNING]	2020-04-21 13:14:05,512	module:log	django.request.log_response:228	Not Found: /favicon.ico
[WARNING]	2020-04-21 13:14:15,911	module:log	django.request.log_response:228	Not Found: /favicon.ico
[WARNING]	2020-04-21 13:14:21,005	module:log	django.request.log_response:228	Not Found: /favicon.ico
[WARNING]	2020-04-21 13:14:28,718	module:log	django.request.log_response:228	Not Found: /favicon.ico
[WARNING]	2020-04-21 13:14:34,808	module:log	django.request.log_response:228	Not Found: /favicon.ico
[WARNING]	2020-04-21 13:14:46,706	module:log	django.request.log_response:228	Not Found: /favicon.ico
[WARNING]	2020-04-21 15:29:53,416	module:log	django.request.log_response:228	Not Found: /favicon.ico
[WARNING]	2020-04-21 15:30:53,330	module:log	django.request.log_response:228	Not Found: /favicon.ico
[ERROR]	2020-04-21 15:31:21,594	module:log	django.request.log_response:228	Internal Server Error: /admin/app_sumo/tran_banzuke_forecast/
Traceback (most recent call last):
  File "/usr/local/lib/python3.7/site-packages/django/db/backends/utils.py", line 85, in _execute
    return self.cursor.execute(sql, params)
  File "/usr/local/lib/python3.7/site-packages/django/db/backends/mysql/base.py", line 71, in execute
    return self.cursor.execute(query, args)
  File "/usr/local/lib/python3.7/site-packages/pymysql/cursors.py", line 165, in execute
    result = self._query(query)
  File "/usr/local/lib/python3.7/site-packages/pymysql/cursors.py", line 321, in _query
    conn.query(q)
  File "/usr/local/lib/python3.7/site-packages/pymysql/connections.py", line 860, in query
    self._affected_rows = self._read_query_result(unbuffered=unbuffered)
  File "/usr/local/lib/python3.7/site-packages/pymysql/connections.py", line 1061, in _read_query_result
    result.read()
  File "/usr/local/lib/python3.7/site-packages/pymysql/connections.py", line 1349, in read
    first_packet = self.connection._read_packet()
  File "/usr/local/lib/python3.7/site-packages/pymysql/connections.py", line 1018, in _read_packet
    packet.check_error()
  File "/usr/local/lib/python3.7/site-packages/pymysql/connections.py", line 384, in check_error
    err.raise_mysql_exception(self._data)
  File "/usr/local/lib/python3.7/site-packages/pymysql/err.py", line 107, in raise_mysql_exception
    raise errorclass(errno, errval)
pymysql.err.ProgrammingError: (1146, "Table 'prj_sports.app_sumo_tran_banzuke_forecast' doesn't exist")

The above exception was the direct cause of the following exception:

Traceback (most recent call last):
  File "/usr/local/lib/python3.7/site-packages/django/core/handlers/exception.py", line 34, in inner
    response = get_response(request)
  File "/usr/local/lib/python3.7/site-packages/django/core/handlers/base.py", line 126, in _get_response
    response = self.process_exception_by_middleware(e, request)
  File "/usr/local/lib/python3.7/site-packages/django/core/handlers/base.py", line 124, in _get_response
    response = wrapped_callback(request, *callback_args, **callback_kwargs)
  File "/usr/local/lib/python3.7/site-packages/django/contrib/admin/options.py", line 604, in wrapper
    return self.admin_site.admin_view(view)(*args, **kwargs)
  File "/usr/local/lib/python3.7/site-packages/django/utils/decorators.py", line 142, in _wrapped_view
    response = view_func(request, *args, **kwargs)
  File "/usr/local/lib/python3.7/site-packages/django/views/decorators/cache.py", line 44, in _wrapped_view_func
    response = view_func(request, *args, **kwargs)
  File "/usr/local/lib/python3.7/site-packages/django/contrib/admin/sites.py", line 223, in inner
    return view(request, *args, **kwargs)
  File "/usr/local/lib/python3.7/site-packages/django/utils/decorators.py", line 45, in _wrapper
    return bound_method(*args, **kwargs)
  File "/usr/local/lib/python3.7/site-packages/django/utils/decorators.py", line 142, in _wrapped_view
    response = view_func(request, *args, **kwargs)
  File "/usr/local/lib/python3.7/site-packages/django/contrib/admin/options.py", line 1675, in changelist_view
    cl = self.get_changelist_instance(request)
  File "/usr/local/lib/python3.7/site-packages/django/contrib/admin/options.py", line 742, in get_changelist_instance
    sortable_by,
  File "/usr/local/lib/python3.7/site-packages/django/contrib/admin/views/main.py", line 81, in __init__
    self.get_results(request)
  File "/usr/local/lib/python3.7/site-packages/django/contrib/admin/views/main.py", line 209, in get_results
    result_count = paginator.count
  File "/usr/local/lib/python3.7/site-packages/django/utils/functional.py", line 37, in __get__
    res = instance.__dict__[self.name] = self.func(instance)
  File "/usr/local/lib/python3.7/site-packages/django/core/paginator.py", line 87, in count
    return self.object_list.count()
  File "/usr/local/lib/python3.7/site-packages/django/db/models/query.py", line 383, in count
    return self.query.get_count(using=self.db)
  File "/usr/local/lib/python3.7/site-packages/django/db/models/sql/query.py", line 498, in get_count
    number = obj.get_aggregation(using, ['__count'])['__count']
  File "/usr/local/lib/python3.7/site-packages/django/db/models/sql/query.py", line 483, in get_aggregation
    result = compiler.execute_sql(SINGLE)
  File "/usr/local/lib/python3.7/site-packages/django/db/models/sql/compiler.py", line 1065, in execute_sql
    cursor.execute(sql, params)
  File "/usr/local/lib/python3.7/site-packages/django/db/backends/utils.py", line 100, in execute
    return super().execute(sql, params)
  File "/usr/local/lib/python3.7/site-packages/django/db/backends/utils.py", line 68, in execute
    return self._execute_with_wrappers(sql, params, many=False, executor=self._execute)
  File "/usr/local/lib/python3.7/site-packages/django/db/backends/utils.py", line 77, in _execute_with_wrappers
    return executor(sql, params, many, context)
  File "/usr/local/lib/python3.7/site-packages/django/db/backends/utils.py", line 85, in _execute
    return self.cursor.execute(sql, params)
  File "/usr/local/lib/python3.7/site-packages/django/db/utils.py", line 89, in __exit__
    raise dj_exc_value.with_traceback(traceback) from exc_value
  File "/usr/local/lib/python3.7/site-packages/django/db/backends/utils.py", line 85, in _execute
    return self.cursor.execute(sql, params)
  File "/usr/local/lib/python3.7/site-packages/django/db/backends/mysql/base.py", line 71, in execute
    return self.cursor.execute(query, args)
  File "/usr/local/lib/python3.7/site-packages/pymysql/cursors.py", line 165, in execute
    result = self._query(query)
  File "/usr/local/lib/python3.7/site-packages/pymysql/cursors.py", line 321, in _query
    conn.query(q)
  File "/usr/local/lib/python3.7/site-packages/pymysql/connections.py", line 860, in query
    self._affected_rows = self._read_query_result(unbuffered=unbuffered)
  File "/usr/local/lib/python3.7/site-packages/pymysql/connections.py", line 1061, in _read_query_result
    result.read()
  File "/usr/local/lib/python3.7/site-packages/pymysql/connections.py", line 1349, in read
    first_packet = self.connection._read_packet()
  File "/usr/local/lib/python3.7/site-packages/pymysql/connections.py", line 1018, in _read_packet
    packet.check_error()
  File "/usr/local/lib/python3.7/site-packages/pymysql/connections.py", line 384, in check_error
    err.raise_mysql_exception(self._data)
  File "/usr/local/lib/python3.7/site-packages/pymysql/err.py", line 107, in raise_mysql_exception
    raise errorclass(errno, errval)
django.db.utils.ProgrammingError: (1146, "Table 'prj_sports.app_sumo_tran_banzuke_forecast' doesn't exist")
[ERROR]	2020-04-21 15:31:24,407	module:log	django.request.log_response:228	Internal Server Error: /admin/app_sumo/tran_banzuke/
Traceback (most recent call last):
  File "/usr/local/lib/python3.7/site-packages/django/db/backends/utils.py", line 85, in _execute
    return self.cursor.execute(sql, params)
  File "/usr/local/lib/python3.7/site-packages/django/db/backends/mysql/base.py", line 71, in execute
    return self.cursor.execute(query, args)
  File "/usr/local/lib/python3.7/site-packages/pymysql/cursors.py", line 165, in execute
    result = self._query(query)
  File "/usr/local/lib/python3.7/site-packages/pymysql/cursors.py", line 321, in _query
    conn.query(q)
  File "/usr/local/lib/python3.7/site-packages/pymysql/connections.py", line 860, in query
    self._affected_rows = self._read_query_result(unbuffered=unbuffered)
  File "/usr/local/lib/python3.7/site-packages/pymysql/connections.py", line 1061, in _read_query_result
    result.read()
  File "/usr/local/lib/python3.7/site-packages/pymysql/connections.py", line 1349, in read
    first_packet = self.connection._read_packet()
  File "/usr/local/lib/python3.7/site-packages/pymysql/connections.py", line 1018, in _read_packet
    packet.check_error()
  File "/usr/local/lib/python3.7/site-packages/pymysql/connections.py", line 384, in check_error
    err.raise_mysql_exception(self._data)
  File "/usr/local/lib/python3.7/site-packages/pymysql/err.py", line 107, in raise_mysql_exception
    raise errorclass(errno, errval)
pymysql.err.InternalError: (1054, "Unknown column 'app_sumo_tran_banzuke.Sys_status_id' in 'field list'")

The above exception was the direct cause of the following exception:

Traceback (most recent call last):
  File "/usr/local/lib/python3.7/site-packages/django/core/handlers/exception.py", line 34, in inner
    response = get_response(request)
  File "/usr/local/lib/python3.7/site-packages/django/core/handlers/base.py", line 126, in _get_response
    response = self.process_exception_by_middleware(e, request)
  File "/usr/local/lib/python3.7/site-packages/django/core/handlers/base.py", line 124, in _get_response
    response = wrapped_callback(request, *callback_args, **callback_kwargs)
  File "/usr/local/lib/python3.7/site-packages/django/contrib/admin/options.py", line 604, in wrapper
    return self.admin_site.admin_view(view)(*args, **kwargs)
  File "/usr/local/lib/python3.7/site-packages/django/utils/decorators.py", line 142, in _wrapped_view
    response = view_func(request, *args, **kwargs)
  File "/usr/local/lib/python3.7/site-packages/django/views/decorators/cache.py", line 44, in _wrapped_view_func
    response = view_func(request, *args, **kwargs)
  File "/usr/local/lib/python3.7/site-packages/django/contrib/admin/sites.py", line 223, in inner
    return view(request, *args, **kwargs)
  File "/usr/local/lib/python3.7/site-packages/django/utils/decorators.py", line 45, in _wrapper
    return bound_method(*args, **kwargs)
  File "/usr/local/lib/python3.7/site-packages/django/utils/decorators.py", line 142, in _wrapped_view
    response = view_func(request, *args, **kwargs)
  File "/usr/local/lib/python3.7/site-packages/django/contrib/admin/options.py", line 1793, in changelist_view
    'selection_note': _('0 of %(cnt)s selected') % {'cnt': len(cl.result_list)},
  File "/usr/local/lib/python3.7/site-packages/django/db/models/query.py", line 250, in __len__
    self._fetch_all()
  File "/usr/local/lib/python3.7/site-packages/django/db/models/query.py", line 1186, in _fetch_all
    self._result_cache = list(self._iterable_class(self))
  File "/usr/local/lib/python3.7/site-packages/django/db/models/query.py", line 54, in __iter__
    results = compiler.execute_sql(chunked_fetch=self.chunked_fetch, chunk_size=self.chunk_size)
  File "/usr/local/lib/python3.7/site-packages/django/db/models/sql/compiler.py", line 1065, in execute_sql
    cursor.execute(sql, params)
  File "/usr/local/lib/python3.7/site-packages/django/db/backends/utils.py", line 100, in execute
    return super().execute(sql, params)
  File "/usr/local/lib/python3.7/site-packages/django/db/backends/utils.py", line 68, in execute
    return self._execute_with_wrappers(sql, params, many=False, executor=self._execute)
  File "/usr/local/lib/python3.7/site-packages/django/db/backends/utils.py", line 77, in _execute_with_wrappers
    return executor(sql, params, many, context)
  File "/usr/local/lib/python3.7/site-packages/django/db/backends/utils.py", line 85, in _execute
    return self.cursor.execute(sql, params)
  File "/usr/local/lib/python3.7/site-packages/django/db/utils.py", line 89, in __exit__
    raise dj_exc_value.with_traceback(traceback) from exc_value
  File "/usr/local/lib/python3.7/site-packages/django/db/backends/utils.py", line 85, in _execute
    return self.cursor.execute(sql, params)
  File "/usr/local/lib/python3.7/site-packages/django/db/backends/mysql/base.py", line 71, in execute
    return self.cursor.execute(query, args)
  File "/usr/local/lib/python3.7/site-packages/pymysql/cursors.py", line 165, in execute
    result = self._query(query)
  File "/usr/local/lib/python3.7/site-packages/pymysql/cursors.py", line 321, in _query
    conn.query(q)
  File "/usr/local/lib/python3.7/site-packages/pymysql/connections.py", line 860, in query
    self._affected_rows = self._read_query_result(unbuffered=unbuffered)
  File "/usr/local/lib/python3.7/site-packages/pymysql/connections.py", line 1061, in _read_query_result
    result.read()
  File "/usr/local/lib/python3.7/site-packages/pymysql/connections.py", line 1349, in read
    first_packet = self.connection._read_packet()
  File "/usr/local/lib/python3.7/site-packages/pymysql/connections.py", line 1018, in _read_packet
    packet.check_error()
  File "/usr/local/lib/python3.7/site-packages/pymysql/connections.py", line 384, in check_error
    err.raise_mysql_exception(self._data)
  File "/usr/local/lib/python3.7/site-packages/pymysql/err.py", line 107, in raise_mysql_exception
    raise errorclass(errno, errval)
django.db.utils.InternalError: (1054, "Unknown column 'app_sumo_tran_banzuke.Sys_status_id' in 'field list'")
[WARNING]	2020-04-21 15:31:39,011	module:log	django.request.log_response:228	Not Found: /favicon.ico
[WARNING]	2020-04-21 15:31:46,337	module:log	django.request.log_response:228	Not Found: /favicon.ico
[WARNING]	2020-04-21 15:31:48,748	module:log	django.request.log_response:228	Not Found: /favicon.ico
[WARNING]	2020-04-21 15:32:09,143	module:log	django.request.log_response:228	Not Found: /favicon.ico
[WARNING]	2020-04-21 15:35:06,241	module:log	django.request.log_response:228	Not Found: /favicon.ico
[ERROR]	2020-04-21 15:38:29,824	module:log	django.request.log_response:228	Internal Server Error: /app_sumo/SUMJOR01/
Traceback (most recent call last):
  File "/usr/local/lib/python3.7/site-packages/django/core/handlers/exception.py", line 34, in inner
    response = get_response(request)
  File "/usr/local/lib/python3.7/site-packages/django/core/handlers/base.py", line 126, in _get_response
    response = self.process_exception_by_middleware(e, request)
  File "/usr/local/lib/python3.7/site-packages/django/core/handlers/base.py", line 124, in _get_response
    response = wrapped_callback(request, *callback_args, **callback_kwargs)
  File "./app_sumo/views.py", line 214, in SUMJOR01
    params = nav_info(request)
  File "./app_sumo/add_views.py", line 24, in nav_info
    'basho':tran_system.CurrentBasho,
AttributeError: 'NoneType' object has no attribute 'CurrentBasho'
[ERROR]	2020-04-21 15:38:40,070	module:log	django.request.log_response:228	Internal Server Error: /app_sumo/SUMUDY01/
Traceback (most recent call last):
  File "/usr/local/lib/python3.7/site-packages/django/core/handlers/exception.py", line 34, in inner
    response = get_response(request)
  File "/usr/local/lib/python3.7/site-packages/django/core/handlers/base.py", line 126, in _get_response
    response = self.process_exception_by_middleware(e, request)
  File "/usr/local/lib/python3.7/site-packages/django/core/handlers/base.py", line 124, in _get_response
    response = wrapped_callback(request, *callback_args, **callback_kwargs)
  File "./app_sumo/views.py", line 35, in SUMUDY01
    "torikumi_nichime": tran_system.TorikumiDate.Nichime_code,
AttributeError: 'NoneType' object has no attribute 'TorikumiDate'
[ERROR]	2020-04-21 16:00:10,831	module:log	django.request.log_response:228	Internal Server Error: /app_sumo/SUMUDY01/
Traceback (most recent call last):
  File "/usr/local/lib/python3.7/site-packages/django/core/handlers/exception.py", line 34, in inner
    response = get_response(request)
  File "/usr/local/lib/python3.7/site-packages/django/core/handlers/base.py", line 126, in _get_response
    response = self.process_exception_by_middleware(e, request)
  File "/usr/local/lib/python3.7/site-packages/django/core/handlers/base.py", line 124, in _get_response
    response = wrapped_callback(request, *callback_args, **callback_kwargs)
  File "./app_sumo/views.py", line 35, in SUMUDY01
    "torikumi_nichime": tran_system.TorikumiDate.Nichime_code,
AttributeError: 'NoneType' object has no attribute 'TorikumiDate'
